{
  "version": 8,
  "blockIdVersion": 11,
  "anchorX": 1,
  "anchorY": 0,
  "anchorZ": 1,
  "blocks": [
    {
      "x": -19,
      "y": 0,
      "z": -17,
      "name": "Soil_Hive_Corrupted_Brick"
    },
    {
      "x": -19,
      "y": 1,
      "z": -17,
      "name": "Soil_Hive_Corrupted_Brick"
    },
    {
      "x": -19,
      "y": 2,
      "z": -17,
      "name": "Soil_Hive_Corrupted_Brick"
    },
    {
      "x": -19,
      "y": 3,
      "z": -17,
      "name": "Soil_Hive_Corrupted_Brick"
    },
    {
      "x": -19,
      "y": 0,
      "z": -16,
      "name": "Soil_Hive_Corrupted_Brick"
    },
    {
      "x": -19,
      "y": 1,
      "z": -16,
      "name": "Soil_Hive_Corrupted_Brick"
    },
    {
      "x": -19,
      "y": 2,
      "z": -16,
      "name": "Soil_Hive_Corrupted_Brick"
    },
    {
      "x": -19,
      "y": 3,
      "z": -16,
      "name": "Soil_Hive_Corrupted_Brick"
    },
    {
      "x": -19,
      "y": 0,
      "z": -15,
      "name": "Soil_Hive_Corrupted_Brick"
    },
    {
      "x": -19,
      "y": 1,
      "z": -15,
      "name": "Soil_Hive_Corrupted_Brick"
    },
    {
      "x": -19,
      "y": 2,
      "z": -15,
      "name": "Soil_Hive_Corrupted_Brick"
    },
    {
      "x": -19,
      "y": 3,
      "z": -15,
      "name": "Soil_Hive_Corrupted_Brick"
    },
    {
      "x": -19,
      "y": 0,
      "z": -13,
      "name": "Soil_Hive_Corrupted_Brick"
    },
    {
      "x": -19,
      "y": 1,
      "z": -13,
      "name": "Soil_Hive_Corrupted_Brick"
    },
    {
      "x": -19,
      "y": 2,
      "z": -13,
      "name": "Soil_Hive_Corrupted_Brick"
    },
    {
      "x": -19,
      "y": 3,
      "z": -13,
      "name": "Soil_Hive_Corrupted_Brick"
    },
    {
      "x": -19,
      "y": 0,
      "z": -12,
      "name": "Soil_Hive_Corrupted_Brick"
    },
    {
      "x": -19,
      "y": 1,
      "z": -12,
      "name": "Soil_Hive_Corrupted_Brick"
    },
    {
      "x": -19,
      "y": 2,
      "z": -12,
      "name": "Soil_Hive_Corrupted_Brick"
    },
    {
      "x": -19,
      "y": 3,
      "z": -12,
      "name": "Soil_Hive_Corrupted_Brick"
    },
    {
      "x": -19,
      "y": 0,
      "z": -11,
      "name": "Soil_Hive_Corrupted_Brick"
    },
    {
      "x": -19,
      "y": 1,
      "z": -11,
      "name": "Soil_Hive_Corrupted_Brick"
    },
    {
      "x": -19,
      "y": 2,
      "z": -11,
      "name": "Soil_Hive_Corrupted_Brick"
    },
    {
      "x": -19,
      "y": 3,
      "z": -11,
      "name": "Soil_Hive_Corrupted_Brick"
    },
    {
      "x": -19,
      "y": 0,
      "z": -9,
      "name": "Soil_Hive_Corrupted_Brick"
    },
    {
      "x": -19,
      "y": 1,
      "z": -9,
      "name": "Soil_Hive_Corrupted_Brick"
    },
    {
      "x": -19,
      "y": 2,
      "z": -9,
      "name": "Soil_Hive_Corrupted_Brick"
    },
    {
      "x": -19,
      "y": 3,
      "z": -9,
      "name": "Soil_Hive_Corrupted_Brick"
    },
    {
      "x": -19,
      "y": 0,
      "z": -8,
      "name": "Soil_Hive_Corrupted_Brick"
    },
    {
      "x": -19,
      "y": 1,
      "z": -8,
      "name": "Soil_Hive_Corrupted_Brick"
    },
    {
      "x": -19,
      "y": 2,
      "z": -8,
      "name": "Soil_Hive_Corrupted_Brick"
    },
    {
      "x": -19,
      "y": 3,
      "z": -8,
      "name": "Soil_Hive_Corrupted_Brick"
    },
    {
      "x": -19,
      "y": 0,
      "z": -7,
      "name": "Soil_Hive_Corrupted_Brick"
    },
    {
      "x": -19,
      "y": 1,
      "z": -7,
      "name": "Soil_Hive_Corrupted_Brick"
    },
    {
      "x": -19,
      "y": 2,
      "z": -7,
      "name": "Soil_Hive_Corrupted_Brick"
    },
    {
      "x": -19,
      "y": 3,
      "z": -7,
      "name": "Soil_Hive_Corrupted_Brick"
    },
    {
      "x": -19,
      "y": 0,
      "z": -4,
      "name": "Soil_Hive_Corrupted_Brick"
    },
    {
      "x": -19,
      "y": 1,
      "z": -4,
      "name": "Soil_Hive_Corrupted_Brick"
    },
    {
      "x": -19,
      "y": 2,
      "z": -4,
      "name": "Soil_Hive_Corrupted_Brick"
    },
    {
      "x": -19,
      "y": 3,
      "z": -4,
      "name": "Soil_Hive_Corrupted_Brick"
    },
    {
      "x": -19,
      "y": 0,
      "z": -3,
      "name": "Soil_Hive_Corrupted_Brick"
    },
    {
      "x": -19,
      "y": 1,
      "z": -3,
      "name": "Soil_Hive_Corrupted_Brick"
    },
    {
      "x": -19,
      "y": 2,
      "z": -3,
      "name": "Soil_Hive_Corrupted_Brick"
    },
    {
      "x": -19,
      "y": 3,
      "z": -3,
      "name": "Soil_Hive_Corrupted_Brick"
    },
    {
      "x": -19,
      "y": 0,
      "z": -2,
      "name": "Soil_Hive_Corrupted_Brick"
    },
    {
      "x": -19,
      "y": 1,
      "z": -2,
      "name": "Soil_Hive_Corrupted_Brick"
    },
    {
      "x": -19,
      "y": 2,
      "z": -2,
      "name": "Soil_Hive_Corrupted_Brick"
    },
    {
      "x": -19,
      "y": 3,
      "z": -2,
      "name": "Soil_Hive_Corrupted_Brick"
    },
    {
      "x": -19,
      "y": 0,
      "z": 0,
      "name": "Soil_Hive_Corrupted_Brick",
      "rotation": 2
    },
    {
      "x": -19,
      "y": 1,
      "z": 0,
      "name": "Soil_Hive_Corrupted_Brick",
      "rotation": 2
    },
    {
      "x": -19,
      "y": 2,
      "z": 0,
      "name": "Soil_Hive_Corrupted_Brick",
      "rotation": 2
    },
    {
      "x": -19,
      "y": 3,
      "z": 0,
      "name": "Soil_Hive_Corrupted_Brick",
      "rotation": 2
    },
    {
      "x": -19,
      "y": 0,
      "z": 1,
      "name": "Soil_Hive_Corrupted_Brick",
      "rotation": 2
    },
    {
      "x": -19,
      "y": 1,
      "z": 1,
      "name": "Soil_Hive_Corrupted_Brick",
      "rotation": 2
    },
    {
      "x": -19,
      "y": 2,
      "z": 1,
      "name": "Soil_Hive_Corrupted_Brick",
      "rotation": 2
    },
    {
      "x": -19,
      "y": 3,
      "z": 1,
      "name": "Soil_Hive_Corrupted_Brick",
      "rotation": 2
    },
    {
      "x": -19,
      "y": 0,
      "z": 2,
      "name": "Soil_Hive_Corrupted_Brick",
      "rotation": 2
    },
    {
      "x": -19,
      "y": 1,
      "z": 2,
      "name": "Soil_Hive_Corrupted_Brick",
      "rotation": 2
    },
    {
      "x": -19,
      "y": 2,
      "z": 2,
      "name": "Soil_Hive_Corrupted_Brick",
      "rotation": 2
    },
    {
      "x": -19,
      "y": 3,
      "z": 2,
      "name": "Soil_Hive_Corrupted_Brick",
      "rotation": 2
    },
    {
      "x": -19,
      "y": 0,
      "z": 4,
      "name": "Soil_Hive_Corrupted_Brick"
    },
    {
      "x": -19,
      "y": 1,
      "z": 4,
      "name": "Soil_Hive_Corrupted_Brick"
    },
    {
      "x": -19,
      "y": 2,
      "z": 4,
      "name": "Soil_Hive_Corrupted_Brick"
    },
    {
      "x": -19,
      "y": 3,
      "z": 4,
      "name": "Soil_Hive_Corrupted_Brick"
    },
    {
      "x": -19,
      "y": 0,
      "z": 5,
      "name": "Soil_Hive_Corrupted_Brick"
    },
    {
      "x": -19,
      "y": 1,
      "z": 5,
      "name": "Soil_Hive_Corrupted_Brick"
    },
    {
      "x": -19,
      "y": 2,
      "z": 5,
      "name": "Soil_Hive_Corrupted_Brick"
    },
    {
      "x": -19,
      "y": 3,
      "z": 5,
      "name": "Soil_Hive_Corrupted_Brick"
    },
    {
      "x": -19,
      "y": 0,
      "z": 6,
      "name": "Soil_Hive_Corrupted_Brick"
    },
    {
      "x": -19,
      "y": 1,
      "z": 6,
      "name": "Soil_Hive_Corrupted_Brick"
    },
    {
      "x": -19,
      "y": 2,
      "z": 6,
      "name": "Soil_Hive_Corrupted_Brick"
    },
    {
      "x": -19,
      "y": 3,
      "z": 6,
      "name": "Soil_Hive_Corrupted_Brick"
    },
    {
      "x": -19,
      "y": 0,
      "z": 9,
      "name": "Soil_Hive_Corrupted_Brick",
      "rotation": 2
    },
    {
      "x": -19,
      "y": 1,
      "z": 9,
      "name": "Soil_Hive_Corrupted_Brick",
      "rotation": 2
    },
    {
      "x": -19,
      "y": 2,
      "z": 9,
      "name": "Soil_Hive_Corrupted_Brick",
      "rotation": 2
    },
    {
      "x": -19,
      "y": 3,
      "z": 9,
      "name": "Soil_Hive_Corrupted_Brick",
      "rotation": 2
    },
    {
      "x": -19,
      "y": 0,
      "z": 10,
      "name": "Soil_Hive_Corrupted_Brick",
      "rotation": 2
    },
    {
      "x": -19,
      "y": 1,
      "z": 10,
      "name": "Soil_Hive_Corrupted_Brick",
      "rotation": 2
    },
    {
      "x": -19,
      "y": 2,
      "z": 10,
      "name": "Soil_Hive_Corrupted_Brick",
      "rotation": 2
    },
    {
      "x": -19,
      "y": 3,
      "z": 10,
      "name": "Soil_Hive_Corrupted_Brick",
      "rotation": 2
    },
    {
      "x": -19,
      "y": 0,
      "z": 11,
      "name": "Soil_Hive_Corrupted_Brick",
      "rotation": 2
    },
    {
      "x": -19,
      "y": 1,
      "z": 11,
      "name": "Soil_Hive_Corrupted_Brick",
      "rotation": 2
    },
    {
      "x": -19,
      "y": 2,
      "z": 11,
      "name": "Soil_Hive_Corrupted_Brick",
      "rotation": 2
    },
    {
      "x": -19,
      "y": 3,
      "z": 11,
      "name": "Soil_Hive_Corrupted_Brick",
      "rotation": 2
    },
    {
      "x": -19,
      "y": 0,
      "z": 14,
      "name": "Soil_Hive_Corrupted_Brick"
    },
    {
      "x": -19,
      "y": 1,
      "z": 14,
      "name": "Soil_Hive_Corrupted_Brick"
    },
    {
      "x": -19,
      "y": 2,
      "z": 14,
      "name": "Soil_Hive_Corrupted_Brick"
    },
    {
      "x": -19,
      "y": 3,
      "z": 14,
      "name": "Soil_Hive_Corrupted_Brick"
    },
    {
      "x": -19,
      "y": 0,
      "z": 15,
      "name": "Soil_Hive_Corrupted_Brick"
    },
    {
      "x": -19,
      "y": 1,
      "z": 15,
      "name": "Soil_Hive_Corrupted_Brick"
    },
    {
      "x": -19,
      "y": 2,
      "z": 15,
      "name": "Soil_Hive_Corrupted_Brick"
    },
    {
      "x": -19,
      "y": 3,
      "z": 15,
      "name": "Soil_Hive_Corrupted_Brick"
    },
    {
      "x": -19,
      "y": 0,
      "z": 16,
      "name": "Soil_Hive_Corrupted_Brick"
    },
    {
      "x": -19,
      "y": 1,
      "z": 16,
      "name": "Soil_Hive_Corrupted_Brick"
    },
    {
      "x": -19,
      "y": 2,
      "z": 16,
      "name": "Soil_Hive_Corrupted_Brick"
    },
    {
      "x": -19,
      "y": 3,
      "z": 16,
      "name": "Soil_Hive_Corrupted_Brick"
    },
    {
      "x": -19,
      "y": 0,
      "z": 17,
      "name": "Soil_Hive_Corrupted_Brick"
    },
    {
      "x": -19,
      "y": 1,
      "z": 17,
      "name": "Soil_Hive_Corrupted_Brick"
    },
    {
      "x": -19,
      "y": 2,
      "z": 17,
      "name": "Soil_Hive_Corrupted_Brick"
    },
    {
      "x": -19,
      "y": 3,
      "z": 17,
      "name": "Soil_Hive_Corrupted_Brick"
    },
    {
      "x": -19,
      "y": 0,
      "z": 18,
      "name": "Soil_Hive_Corrupted_Brick"
    },
    {
      "x": -19,
      "y": 1,
      "z": 18,
      "name": "Soil_Hive_Corrupted_Brick"
    },
    {
      "x": -19,
      "y": 2,
      "z": 18,
      "name": "Soil_Hive_Corrupted_Brick"
    },
    {
      "x": -19,
      "y": 3,
      "z": 18,
      "name": "Soil_Hive_Corrupted_Brick"
    },
    {
      "x": -18,
      "y": 0,
      "z": -18,
      "name": "Rock_Bedrock"
    },
    {
      "x": -18,
      "y": 1,
      "z": -18,
      "name": "Rock_Bedrock"
    },
    {
      "x": -18,
      "y": 2,
      "z": -18,
      "name": "Rock_Bedrock"
    },
    {
      "x": -18,
      "y": 3,
      "z": -18,
      "name": "Rock_Bedrock"
    },
    {
      "x": -18,
      "y": 0,
      "z": -17,
      "name": "Rock_Bedrock"
    },
    {
      "x": -18,
      "y": 1,
      "z": -17,
      "name": "Rock_Bedrock"
    },
    {
      "x": -18,
      "y": 2,
      "z": -17,
      "name": "Rock_Bedrock"
    },
    {
      "x": -18,
      "y": 3,
      "z": -17,
      "name": "Rock_Bedrock"
    },
    {
      "x": -18,
      "y": 0,
      "z": -16,
      "name": "Rock_Bedrock"
    },
    {
      "x": -18,
      "y": 1,
      "z": -16,
      "name": "Rock_Bedrock"
    },
    {
      "x": -18,
      "y": 2,
      "z": -16,
      "name": "Rock_Bedrock"
    },
    {
      "x": -18,
      "y": 3,
      "z": -16,
      "name": "Rock_Bedrock"
    },
    {
      "x": -18,
      "y": 0,
      "z": -15,
      "name": "Rock_Bedrock"
    },
    {
      "x": -18,
      "y": 1,
      "z": -15,
      "name": "Rock_Bedrock"
    },
    {
      "x": -18,
      "y": 2,
      "z": -15,
      "name": "Rock_Bedrock"
    },
    {
      "x": -18,
      "y": 3,
      "z": -15,
      "name": "Rock_Bedrock"
    },
    {
      "x": -18,
      "y": 0,
      "z": -14,
      "name": "Rock_Bedrock"
    },
    {
      "x": -18,
      "y": 1,
      "z": -14,
      "name": "Rock_Bedrock"
    },
    {
      "x": -18,
      "y": 2,
      "z": -14,
      "name": "Rock_Bedrock"
    },
    {
      "x": -18,
      "y": 3,
      "z": -14,
      "name": "Rock_Bedrock"
    },
    {
      "x": -18,
      "y": 0,
      "z": -13,
      "name": "Rock_Bedrock"
    },
    {
      "x": -18,
      "y": 1,
      "z": -13,
      "name": "Rock_Bedrock"
    },
    {
      "x": -18,
      "y": 2,
      "z": -13,
      "name": "Rock_Bedrock"
    },
    {
      "x": -18,
      "y": 3,
      "z": -13,
      "name": "Rock_Bedrock"
    },
    {
      "x": -18,
      "y": 0,
      "z": -12,
      "name": "Rock_Bedrock"
    },
    {
      "x": -18,
      "y": 1,
      "z": -12,
      "name": "Rock_Bedrock"
    },
    {
      "x": -18,
      "y": 2,
      "z": -12,
      "name": "Rock_Bedrock"
    },
    {
      "x": -18,
      "y": 3,
      "z": -12,
      "name": "Rock_Bedrock"
    },
    {
      "x": -18,
      "y": 0,
      "z": -11,
      "name": "Rock_Bedrock"
    },
    {
      "x": -18,
      "y": 1,
      "z": -11,
      "name": "Rock_Bedrock"
    },
    {
      "x": -18,
      "y": 2,
      "z": -11,
      "name": "Rock_Bedrock"
    },
    {
      "x": -18,
      "y": 3,
      "z": -11,
      "name": "Rock_Bedrock"
    },
    {
      "x": -18,
      "y": 0,
      "z": -10,
      "name": "Rock_Bedrock"
    },
    {
      "x": -18,
      "y": 1,
      "z": -10,
      "name": "Rock_Bedrock"
    },
    {
      "x": -18,
      "y": 2,
      "z": -10,
      "name": "Rock_Bedrock"
    },
    {
      "x": -18,
      "y": 3,
      "z": -10,
      "name": "Rock_Bedrock"
    },
    {
      "x": -18,
      "y": 0,
      "z": -9,
      "name": "Rock_Bedrock"
    },
    {
      "x": -18,
      "y": 1,
      "z": -9,
      "name": "Rock_Bedrock"
    },
    {
      "x": -18,
      "y": 2,
      "z": -9,
      "name": "Rock_Bedrock"
    },
    {
      "x": -18,
      "y": 3,
      "z": -9,
      "name": "Rock_Bedrock"
    },
    {
      "x": -18,
      "y": 0,
      "z": -8,
      "name": "Rock_Bedrock"
    },
    {
      "x": -18,
      "y": 1,
      "z": -8,
      "name": "Rock_Bedrock"
    },
    {
      "x": -18,
      "y": 2,
      "z": -8,
      "name": "Rock_Bedrock"
    },
    {
      "x": -18,
      "y": 3,
      "z": -8,
      "name": "Rock_Bedrock"
    },
    {
      "x": -18,
      "y": 0,
      "z": -7,
      "name": "Rock_Bedrock"
    },
    {
      "x": -18,
      "y": 1,
      "z": -7,
      "name": "Rock_Bedrock"
    },
    {
      "x": -18,
      "y": 2,
      "z": -7,
      "name": "Rock_Bedrock"
    },
    {
      "x": -18,
      "y": 3,
      "z": -7,
      "name": "Rock_Bedrock"
    },
    {
      "x": -18,
      "y": 0,
      "z": -6,
      "name": "Rock_Bedrock"
    },
    {
      "x": -18,
      "y": 1,
      "z": -6,
      "name": "Rock_Bedrock"
    },
    {
      "x": -18,
      "y": 2,
      "z": -6,
      "name": "Rock_Bedrock"
    },
    {
      "x": -18,
      "y": 3,
      "z": -6,
      "name": "Rock_Bedrock"
    },
    {
      "x": -18,
      "y": 0,
      "z": -5,
      "name": "Rock_Bedrock"
    },
    {
      "x": -18,
      "y": 1,
      "z": -5,
      "name": "Rock_Bedrock"
    },
    {
      "x": -18,
      "y": 2,
      "z": -5,
      "name": "Rock_Bedrock"
    },
    {
      "x": -18,
      "y": 3,
      "z": -5,
      "name": "Rock_Bedrock"
    },
    {
      "x": -18,
      "y": 0,
      "z": -4,
      "name": "Rock_Bedrock"
    },
    {
      "x": -18,
      "y": 1,
      "z": -4,
      "name": "Rock_Bedrock"
    },
    {
      "x": -18,
      "y": 2,
      "z": -4,
      "name": "Rock_Bedrock"
    },
    {
      "x": -18,
      "y": 3,
      "z": -4,
      "name": "Rock_Bedrock"
    },
    {
      "x": -18,
      "y": 0,
      "z": -3,
      "name": "Rock_Bedrock"
    },
    {
      "x": -18,
      "y": 1,
      "z": -3,
      "name": "Rock_Bedrock"
    },
    {
      "x": -18,
      "y": 2,
      "z": -3,
      "name": "Rock_Bedrock"
    },
    {
      "x": -18,
      "y": 3,
      "z": -3,
      "name": "Rock_Bedrock"
    },
    {
      "x": -18,
      "y": 0,
      "z": -2,
      "name": "Rock_Bedrock"
    },
    {
      "x": -18,
      "y": 1,
      "z": -2,
      "name": "Rock_Bedrock"
    },
    {
      "x": -18,
      "y": 2,
      "z": -2,
      "name": "Rock_Bedrock"
    },
    {
      "x": -18,
      "y": 3,
      "z": -2,
      "name": "Rock_Bedrock"
    },
    {
      "x": -18,
      "y": 0,
      "z": -1,
      "name": "Rock_Bedrock"
    },
    {
      "x": -18,
      "y": 1,
      "z": -1,
      "name": "Rock_Bedrock"
    },
    {
      "x": -18,
      "y": 2,
      "z": -1,
      "name": "Rock_Bedrock"
    },
    {
      "x": -18,
      "y": 3,
      "z": -1,
      "name": "Rock_Bedrock"
    },
    {
      "x": -18,
      "y": 0,
      "z": 0,
      "name": "Rock_Bedrock"
    },
    {
      "x": -18,
      "y": 1,
      "z": 0,
      "name": "Rock_Bedrock"
    },
    {
      "x": -18,
      "y": 2,
      "z": 0,
      "name": "Rock_Bedrock"
    },
    {
      "x": -18,
      "y": 3,
      "z": 0,
      "name": "Rock_Bedrock"
    },
    {
      "x": -18,
      "y": 0,
      "z": 1,
      "name": "Rock_Bedrock"
    },
    {
      "x": -18,
      "y": 1,
      "z": 1,
      "name": "Rock_Bedrock"
    },
    {
      "x": -18,
      "y": 2,
      "z": 1,
      "name": "Rock_Bedrock"
    },
    {
      "x": -18,
      "y": 3,
      "z": 1,
      "name": "Rock_Bedrock"
    },
    {
      "x": -18,
      "y": 0,
      "z": 2,
      "name": "Rock_Bedrock"
    },
    {
      "x": -18,
      "y": 1,
      "z": 2,
      "name": "Rock_Bedrock"
    },
    {
      "x": -18,
      "y": 2,
      "z": 2,
      "name": "Rock_Bedrock"
    },
    {
      "x": -18,
      "y": 3,
      "z": 2,
      "name": "Rock_Bedrock"
    },
    {
      "x": -18,
      "y": 0,
      "z": 3,
      "name": "Rock_Bedrock"
    },
    {
      "x": -18,
      "y": 1,
      "z": 3,
      "name": "Rock_Bedrock"
    },
    {
      "x": -18,
      "y": 2,
      "z": 3,
      "name": "Rock_Bedrock"
    },
    {
      "x": -18,
      "y": 3,
      "z": 3,
      "name": "Rock_Bedrock"
    },
    {
      "x": -18,
      "y": 0,
      "z": 4,
      "name": "Rock_Bedrock"
    },
    {
      "x": -18,
      "y": 1,
      "z": 4,
      "name": "Rock_Bedrock"
    },
    {
      "x": -18,
      "y": 2,
      "z": 4,
      "name": "Rock_Bedrock"
    },
    {
      "x": -18,
      "y": 3,
      "z": 4,
      "name": "Rock_Bedrock"
    },
    {
      "x": -18,
      "y": 0,
      "z": 5,
      "name": "Rock_Bedrock"
    },
    {
      "x": -18,
      "y": 1,
      "z": 5,
      "name": "Rock_Bedrock"
    },
    {
      "x": -18,
      "y": 2,
      "z": 5,
      "name": "Rock_Bedrock"
    },
    {
      "x": -18,
      "y": 3,
      "z": 5,
      "name": "Rock_Bedrock"
    },
    {
      "x": -18,
      "y": 0,
      "z": 6,
      "name": "Rock_Bedrock"
    },
    {
      "x": -18,
      "y": 1,
      "z": 6,
      "name": "Rock_Bedrock"
    },
    {
      "x": -18,
      "y": 2,
      "z": 6,
      "name": "Rock_Bedrock"
    },
    {
      "x": -18,
      "y": 3,
      "z": 6,
      "name": "Rock_Bedrock"
    },
    {
      "x": -18,
      "y": 0,
      "z": 7,
      "name": "Rock_Bedrock"
    },
    {
      "x": -18,
      "y": 1,
      "z": 7,
      "name": "Rock_Bedrock"
    },
    {
      "x": -18,
      "y": 2,
      "z": 7,
      "name": "Rock_Bedrock"
    },
    {
      "x": -18,
      "y": 3,
      "z": 7,
      "name": "Rock_Bedrock"
    },
    {
      "x": -18,
      "y": 0,
      "z": 8,
      "name": "Rock_Bedrock"
    },
    {
      "x": -18,
      "y": 1,
      "z": 8,
      "name": "Rock_Bedrock"
    },
    {
      "x": -18,
      "y": 2,
      "z": 8,
      "name": "Rock_Bedrock"
    },
    {
      "x": -18,
      "y": 3,
      "z": 8,
      "name": "Rock_Bedrock"
    },
    {
      "x": -18,
      "y": 0,
      "z": 9,
      "name": "Rock_Bedrock"
    },
    {
      "x": -18,
      "y": 1,
      "z": 9,
      "name": "Rock_Bedrock"
    },
    {
      "x": -18,
      "y": 2,
      "z": 9,
      "name": "Rock_Bedrock"
    },
    {
      "x": -18,
      "y": 3,
      "z": 9,
      "name": "Rock_Bedrock"
    },
    {
      "x": -18,
      "y": 0,
      "z": 10,
      "name": "Rock_Bedrock"
    },
    {
      "x": -18,
      "y": 1,
      "z": 10,
      "name": "Rock_Bedrock"
    },
    {
      "x": -18,
      "y": 2,
      "z": 10,
      "name": "Rock_Bedrock"
    },
    {
      "x": -18,
      "y": 3,
      "z": 10,
      "name": "Rock_Bedrock"
    },
    {
      "x": -18,
      "y": 0,
      "z": 11,
      "name": "Rock_Bedrock"
    },
    {
      "x": -18,
      "y": 1,
      "z": 11,
      "name": "Rock_Bedrock"
    },
    {
      "x": -18,
      "y": 2,
      "z": 11,
      "name": "Rock_Bedrock"
    },
    {
      "x": -18,
      "y": 3,
      "z": 11,
      "name": "Rock_Bedrock"
    },
    {
      "x": -18,
      "y": 0,
      "z": 12,
      "name": "Rock_Bedrock"
    },
    {
      "x": -18,
      "y": 1,
      "z": 12,
      "name": "Rock_Bedrock"
    },
    {
      "x": -18,
      "y": 2,
      "z": 12,
      "name": "Rock_Bedrock"
    },
    {
      "x": -18,
      "y": 3,
      "z": 12,
      "name": "Rock_Bedrock"
    },
    {
      "x": -18,
      "y": 0,
      "z": 13,
      "name": "Rock_Bedrock"
    },
    {
      "x": -18,
      "y": 1,
      "z": 13,
      "name": "Rock_Bedrock"
    },
    {
      "x": -18,
      "y": 2,
      "z": 13,
      "name": "Rock_Bedrock"
    },
    {
      "x": -18,
      "y": 3,
      "z": 13,
      "name": "Rock_Bedrock"
    },
    {
      "x": -18,
      "y": 0,
      "z": 14,
      "name": "Rock_Bedrock"
    },
    {
      "x": -18,
      "y": 1,
      "z": 14,
      "name": "Rock_Bedrock"
    },
    {
      "x": -18,
      "y": 2,
      "z": 14,
      "name": "Rock_Bedrock"
    },
    {
      "x": -18,
      "y": 3,
      "z": 14,
      "name": "Rock_Bedrock"
    },
    {
      "x": -18,
      "y": 0,
      "z": 15,
      "name": "Rock_Bedrock"
    },
    {
      "x": -18,
      "y": 1,
      "z": 15,
      "name": "Rock_Bedrock"
    },
    {
      "x": -18,
      "y": 2,
      "z": 15,
      "name": "Rock_Bedrock"
    },
    {
      "x": -18,
      "y": 3,
      "z": 15,
      "name": "Rock_Bedrock"
    },
    {
      "x": -18,
      "y": 0,
      "z": 16,
      "name": "Rock_Bedrock"
    },
    {
      "x": -18,
      "y": 1,
      "z": 16,
      "name": "Rock_Bedrock"
    },
    {
      "x": -18,
      "y": 2,
      "z": 16,
      "name": "Rock_Bedrock"
    },
    {
      "x": -18,
      "y": 3,
      "z": 16,
      "name": "Rock_Bedrock"
    },
    {
      "x": -18,
      "y": 0,
      "z": 17,
      "name": "Rock_Bedrock"
    },
    {
      "x": -18,
      "y": 1,
      "z": 17,
      "name": "Rock_Bedrock"
    },
    {
      "x": -18,
      "y": 2,
      "z": 17,
      "name": "Rock_Bedrock"
    },
    {
      "x": -18,
      "y": 3,
      "z": 17,
      "name": "Rock_Bedrock"
    },
    {
      "x": -18,
      "y": 0,
      "z": 18,
      "name": "Rock_Bedrock"
    },
    {
      "x": -18,
      "y": 1,
      "z": 18,
      "name": "Rock_Bedrock"
    },
    {
      "x": -18,
      "y": 2,
      "z": 18,
      "name": "Rock_Bedrock"
    },
    {
      "x": -18,
      "y": 3,
      "z": 18,
      "name": "Rock_Bedrock"
    },
    {
      "x": -18,
      "y": 0,
      "z": 19,
      "name": "Rock_Bedrock"
    },
    {
      "x": -18,
      "y": 1,
      "z": 19,
      "name": "Rock_Bedrock"
    },
    {
      "x": -18,
      "y": 2,
      "z": 19,
      "name": "Rock_Bedrock"
    },
    {
      "x": -18,
      "y": 3,
      "z": 19,
      "name": "Rock_Bedrock"
    },
    {
      "x": -18,
      "y": 0,
      "z": 20,
      "name": "Rock_Bedrock"
    },
    {
      "x": -18,
      "y": 1,
      "z": 20,
      "name": "Rock_Bedrock"
    },
    {
      "x": -18,
      "y": 2,
      "z": 20,
      "name": "Rock_Bedrock"
    },
    {
      "x": -18,
      "y": 3,
      "z": 20,
      "name": "Rock_Bedrock"
    },
    {
      "x": -18,
      "y": 0,
      "z": 21,
      "name": "Soil_Hive_Corrupted_Brick",
      "rotation": 1
    },
    {
      "x": -18,
      "y": 1,
      "z": 21,
      "name": "Soil_Hive_Corrupted_Brick",
      "rotation": 1
    },
    {
      "x": -18,
      "y": 2,
      "z": 21,
      "name": "Soil_Hive_Corrupted_Brick",
      "rotation": 1
    },
    {
      "x": -18,
      "y": 3,
      "z": 21,
      "name": "Soil_Hive_Corrupted_Brick",
      "rotation": 1
    },
    {
      "x": -17,
      "y": 0,
      "z": -18,
      "name": "Rock_Bedrock"
    },
    {
      "x": -17,
      "y": 1,
      "z": -18,
      "name": "Rock_Bedrock"
    },
    {
      "x": -17,
      "y": 2,
      "z": -18,
      "name": "Rock_Bedrock"
    },
    {
      "x": -17,
      "y": 3,
      "z": -18,
      "name": "Rock_Bedrock"
    },
    {
      "x": -17,
      "y": 0,
      "z": 20,
      "name": "Rock_Bedrock"
    },
    {
      "x": -17,
      "y": 1,
      "z": 20,
      "name": "Rock_Bedrock"
    },
    {
      "x": -17,
      "y": 2,
      "z": 20,
      "name": "Rock_Bedrock"
    },
    {
      "x": -17,
      "y": 3,
      "z": 20,
      "name": "Rock_Bedrock"
    },
    {
      "x": -17,
      "y": 0,
      "z": 21,
      "name": "Soil_Hive_Corrupted_Brick",
      "rotation": 1
    },
    {
      "x": -17,
      "y": 1,
      "z": 21,
      "name": "Soil_Hive_Corrupted_Brick",
      "rotation": 1
    },
    {
      "x": -17,
      "y": 2,
      "z": 21,
      "name": "Soil_Hive_Corrupted_Brick",
      "rotation": 1
    },
    {
      "x": -17,
      "y": 3,
      "z": 21,
      "name": "Soil_Hive_Corrupted_Brick",
      "rotation": 1
    },
    {
      "x": -16,
      "y": 0,
      "z": -18,
      "name": "Rock_Bedrock"
    },
    {
      "x": -16,
      "y": 1,
      "z": -18,
      "name": "Rock_Bedrock"
    },
    {
      "x": -16,
      "y": 2,
      "z": -18,
      "name": "Rock_Bedrock"
    },
    {
      "x": -16,
      "y": 3,
      "z": -18,
      "name": "Rock_Bedrock"
    },
    {
      "x": -16,
      "y": 0,
      "z": 20,
      "name": "Rock_Bedrock"
    },
    {
      "x": -16,
      "y": 1,
      "z": 20,
      "name": "Rock_Bedrock"
    },
    {
      "x": -16,
      "y": 2,
      "z": 20,
      "name": "Rock_Bedrock"
    },
    {
      "x": -16,
      "y": 3,
      "z": 20,
      "name": "Rock_Bedrock"
    },
    {
      "x": -16,
      "y": 0,
      "z": 21,
      "name": "Soil_Hive_Corrupted_Brick",
      "rotation": 1
    },
    {
      "x": -16,
      "y": 1,
      "z": 21,
      "name": "Soil_Hive_Corrupted_Brick",
      "rotation": 1
    },
    {
      "x": -16,
      "y": 2,
      "z": 21,
      "name": "Soil_Hive_Corrupted_Brick",
      "rotation": 1
    },
    {
      "x": -16,
      "y": 3,
      "z": 21,
      "name": "Soil_Hive_Corrupted_Brick",
      "rotation": 1
    },
    {
      "x": -15,
      "y": 0,
      "z": -19,
      "name": "Soil_Hive_Corrupted_Brick",
      "rotation": 3
    },
    {
      "x": -15,
      "y": 1,
      "z": -19,
      "name": "Soil_Hive_Corrupted_Brick",
      "rotation": 3
    },
    {
      "x": -15,
      "y": 2,
      "z": -19,
      "name": "Soil_Hive_Corrupted_Brick",
      "rotation": 3
    },
    {
      "x": -15,
      "y": 3,
      "z": -19,
      "name": "Soil_Hive_Corrupted_Brick",
      "rotation": 3
    },
    {
      "x": -15,
      "y": 0,
      "z": -18,
      "name": "Rock_Bedrock"
    },
    {
      "x": -15,
      "y": 1,
      "z": -18,
      "name": "Rock_Bedrock"
    },
    {
      "x": -15,
      "y": 2,
      "z": -18,
      "name": "Rock_Bedrock"
    },
    {
      "x": -15,
      "y": 3,
      "z": -18,
      "name": "Rock_Bedrock"
    },
    {
      "x": -15,
      "y": 0,
      "z": 20,
      "name": "Rock_Bedrock"
    },
    {
      "x": -15,
      "y": 1,
      "z": 20,
      "name": "Rock_Bedrock"
    },
    {
      "x": -15,
      "y": 2,
      "z": 20,
      "name": "Rock_Bedrock"
    },
    {
      "x": -15,
      "y": 3,
      "z": 20,
      "name": "Rock_Bedrock"
    },
    {
      "x": -14,
      "y": 0,
      "z": -19,
      "name": "Soil_Hive_Corrupted_Brick",
      "rotation": 3
    },
    {
      "x": -14,
      "y": 1,
      "z": -19,
      "name": "Soil_Hive_Corrupted_Brick",
      "rotation": 3
    },
    {
      "x": -14,
      "y": 2,
      "z": -19,
      "name": "Soil_Hive_Corrupted_Brick",
      "rotation": 3
    },
    {
      "x": -14,
      "y": 3,
      "z": -19,
      "name": "Soil_Hive_Corrupted_Brick",
      "rotation": 3
    },
    {
      "x": -14,
      "y": 0,
      "z": -18,
      "name": "Rock_Bedrock"
    },
    {
      "x": -14,
      "y": 1,
      "z": -18,
      "name": "Rock_Bedrock"
    },
    {
      "x": -14,
      "y": 2,
      "z": -18,
      "name": "Rock_Bedrock"
    },
    {
      "x": -14,
      "y": 3,
      "z": -18,
      "name": "Rock_Bedrock"
    },
    {
      "x": -14,
      "y": 0,
      "z": 20,
      "name": "Rock_Bedrock"
    },
    {
      "x": -14,
      "y": 1,
      "z": 20,
      "name": "Rock_Bedrock"
    },
    {
      "x": -14,
      "y": 2,
      "z": 20,
      "name": "Rock_Bedrock"
    },
    {
      "x": -14,
      "y": 3,
      "z": 20,
      "name": "Rock_Bedrock"
    },
    {
      "x": -14,
      "y": 0,
      "z": 21,
      "name": "Soil_Hive_Corrupted_Brick",
      "rotation": 1
    },
    {
      "x": -14,
      "y": 1,
      "z": 21,
      "name": "Soil_Hive_Corrupted_Brick",
      "rotation": 1
    },
    {
      "x": -14,
      "y": 2,
      "z": 21,
      "name": "Soil_Hive_Corrupted_Brick",
      "rotation": 1
    },
    {
      "x": -14,
      "y": 3,
      "z": 21,
      "name": "Soil_Hive_Corrupted_Brick",
      "rotation": 1
    },
    {
      "x": -13,
      "y": 0,
      "z": -19,
      "name": "Soil_Hive_Corrupted_Brick",
      "rotation": 3
    },
    {
      "x": -13,
      "y": 1,
      "z": -19,
      "name": "Soil_Hive_Corrupted_Brick",
      "rotation": 3
    },
    {
      "x": -13,
      "y": 2,
      "z": -19,
      "name": "Soil_Hive_Corrupted_Brick",
      "rotation": 3
    },
    {
      "x": -13,
      "y": 3,
      "z": -19,
      "name": "Soil_Hive_Corrupted_Brick",
      "rotation": 3
    },
    {
      "x": -13,
      "y": 0,
      "z": -18,
      "name": "Rock_Bedrock"
    },
    {
      "x": -13,
      "y": 1,
      "z": -18,
      "name": "Rock_Bedrock"
    },
    {
      "x": -13,
      "y": 2,
      "z": -18,
      "name": "Rock_Bedrock"
    },
    {
      "x": -13,
      "y": 3,
      "z": -18,
      "name": "Rock_Bedrock"
    },
    {
      "x": -13,
      "y": 0,
      "z": 20,
      "name": "Rock_Bedrock"
    },
    {
      "x": -13,
      "y": 1,
      "z": 20,
      "name": "Rock_Bedrock"
    },
    {
      "x": -13,
      "y": 2,
      "z": 20,
      "name": "Rock_Bedrock"
    },
    {
      "x": -13,
      "y": 3,
      "z": 20,
      "name": "Rock_Bedrock"
    },
    {
      "x": -13,
      "y": 0,
      "z": 21,
      "name": "Soil_Hive_Corrupted_Brick",
      "rotation": 1
    },
    {
      "x": -13,
      "y": 1,
      "z": 21,
      "name": "Soil_Hive_Corrupted_Brick",
      "rotation": 1
    },
    {
      "x": -13,
      "y": 2,
      "z": 21,
      "name": "Soil_Hive_Corrupted_Brick",
      "rotation": 1
    },
    {
      "x": -13,
      "y": 3,
      "z": 21,
      "name": "Soil_Hive_Corrupted_Brick",
      "rotation": 1
    },
    {
      "x": -12,
      "y": 0,
      "z": -19,
      "name": "Soil_Hive_Corrupted_Brick",
      "rotation": 3
    },
    {
      "x": -12,
      "y": 1,
      "z": -19,
      "name": "Soil_Hive_Corrupted_Brick",
      "rotation": 3
    },
    {
      "x": -12,
      "y": 2,
      "z": -19,
      "name": "Soil_Hive_Corrupted_Brick",
      "rotation": 3
    },
    {
      "x": -12,
      "y": 3,
      "z": -19,
      "name": "Soil_Hive_Corrupted_Brick",
      "rotation": 3
    },
    {
      "x": -12,
      "y": 0,
      "z": -18,
      "name": "Rock_Bedrock"
    },
    {
      "x": -12,
      "y": 1,
      "z": -18,
      "name": "Rock_Bedrock"
    },
    {
      "x": -12,
      "y": 2,
      "z": -18,
      "name": "Rock_Bedrock"
    },
    {
      "x": -12,
      "y": 3,
      "z": -18,
      "name": "Rock_Bedrock"
    },
    {
      "x": -12,
      "y": 0,
      "z": 20,
      "name": "Rock_Bedrock"
    },
    {
      "x": -12,
      "y": 1,
      "z": 20,
      "name": "Rock_Bedrock"
    },
    {
      "x": -12,
      "y": 2,
      "z": 20,
      "name": "Rock_Bedrock"
    },
    {
      "x": -12,
      "y": 3,
      "z": 20,
      "name": "Rock_Bedrock"
    },
    {
      "x": -12,
      "y": 0,
      "z": 21,
      "name": "Soil_Hive_Corrupted_Brick",
      "rotation": 1
    },
    {
      "x": -12,
      "y": 1,
      "z": 21,
      "name": "Soil_Hive_Corrupted_Brick",
      "rotation": 1
    },
    {
      "x": -12,
      "y": 2,
      "z": 21,
      "name": "Soil_Hive_Corrupted_Brick",
      "rotation": 1
    },
    {
      "x": -12,
      "y": 3,
      "z": 21,
      "name": "Soil_Hive_Corrupted_Brick",
      "rotation": 1
    },
    {
      "x": -11,
      "y": 0,
      "z": -19,
      "name": "Soil_Hive_Corrupted_Brick",
      "rotation": 3
    },
    {
      "x": -11,
      "y": 1,
      "z": -19,
      "name": "Soil_Hive_Corrupted_Brick",
      "rotation": 3
    },
    {
      "x": -11,
      "y": 2,
      "z": -19,
      "name": "Soil_Hive_Corrupted_Brick",
      "rotation": 3
    },
    {
      "x": -11,
      "y": 3,
      "z": -19,
      "name": "Soil_Hive_Corrupted_Brick",
      "rotation": 3
    },
    {
      "x": -11,
      "y": 0,
      "z": -18,
      "name": "Rock_Bedrock"
    },
    {
      "x": -11,
      "y": 1,
      "z": -18,
      "name": "Rock_Bedrock"
    },
    {
      "x": -11,
      "y": 2,
      "z": -18,
      "name": "Rock_Bedrock"
    },
    {
      "x": -11,
      "y": 3,
      "z": -18,
      "name": "Rock_Bedrock"
    },
    {
      "x": -11,
      "y": 0,
      "z": 20,
      "name": "Rock_Bedrock"
    },
    {
      "x": -11,
      "y": 1,
      "z": 20,
      "name": "Rock_Bedrock"
    },
    {
      "x": -11,
      "y": 2,
      "z": 20,
      "name": "Rock_Bedrock"
    },
    {
      "x": -11,
      "y": 3,
      "z": 20,
      "name": "Rock_Bedrock"
    },
    {
      "x": -10,
      "y": 0,
      "z": -18,
      "name": "Rock_Bedrock"
    },
    {
      "x": -10,
      "y": 1,
      "z": -18,
      "name": "Rock_Bedrock"
    },
    {
      "x": -10,
      "y": 2,
      "z": -18,
      "name": "Rock_Bedrock"
    },
    {
      "x": -10,
      "y": 3,
      "z": -18,
      "name": "Rock_Bedrock"
    },
    {
      "x": -10,
      "y": 0,
      "z": 20,
      "name": "Rock_Bedrock"
    },
    {
      "x": -10,
      "y": 1,
      "z": 20,
      "name": "Rock_Bedrock"
    },
    {
      "x": -10,
      "y": 2,
      "z": 20,
      "name": "Rock_Bedrock"
    },
    {
      "x": -10,
      "y": 3,
      "z": 20,
      "name": "Rock_Bedrock"
    },
    {
      "x": -10,
      "y": 0,
      "z": 21,
      "name": "Soil_Hive_Corrupted_Brick",
      "rotation": 1
    },
    {
      "x": -10,
      "y": 1,
      "z": 21,
      "name": "Soil_Hive_Corrupted_Brick",
      "rotation": 1
    },
    {
      "x": -10,
      "y": 2,
      "z": 21,
      "name": "Soil_Hive_Corrupted_Brick",
      "rotation": 1
    },
    {
      "x": -10,
      "y": 3,
      "z": 21,
      "name": "Soil_Hive_Corrupted_Brick",
      "rotation": 1
    },
    {
      "x": -9,
      "y": 0,
      "z": -18,
      "name": "Rock_Bedrock"
    },
    {
      "x": -9,
      "y": 1,
      "z": -18,
      "name": "Rock_Bedrock"
    },
    {
      "x": -9,
      "y": 2,
      "z": -18,
      "name": "Rock_Bedrock"
    },
    {
      "x": -9,
      "y": 3,
      "z": -18,
      "name": "Rock_Bedrock"
    },
    {
      "x": -9,
      "y": 0,
      "z": 20,
      "name": "Rock_Bedrock"
    },
    {
      "x": -9,
      "y": 1,
      "z": 20,
      "name": "Rock_Bedrock"
    },
    {
      "x": -9,
      "y": 2,
      "z": 20,
      "name": "Rock_Bedrock"
    },
    {
      "x": -9,
      "y": 3,
      "z": 20,
      "name": "Rock_Bedrock"
    },
    {
      "x": -9,
      "y": 0,
      "z": 21,
      "name": "Soil_Hive_Corrupted_Brick",
      "rotation": 1
    },
    {
      "x": -9,
      "y": 1,
      "z": 21,
      "name": "Soil_Hive_Corrupted_Brick",
      "rotation": 1
    },
    {
      "x": -9,
      "y": 2,
      "z": 21,
      "name": "Soil_Hive_Corrupted_Brick",
      "rotation": 1
    },
    {
      "x": -9,
      "y": 3,
      "z": 21,
      "name": "Soil_Hive_Corrupted_Brick",
      "rotation": 1
    },
    {
      "x": -8,
      "y": 0,
      "z": -19,
      "name": "Soil_Hive_Corrupted_Brick",
      "rotation": 1
    },
    {
      "x": -8,
      "y": 1,
      "z": -19,
      "name": "Soil_Hive_Corrupted_Brick",
      "rotation": 1
    },
    {
      "x": -8,
      "y": 2,
      "z": -19,
      "name": "Soil_Hive_Corrupted_Brick",
      "rotation": 1
    },
    {
      "x": -8,
      "y": 3,
      "z": -19,
      "name": "Soil_Hive_Corrupted_Brick",
      "rotation": 1
    },
    {
      "x": -8,
      "y": 0,
      "z": -18,
      "name": "Rock_Bedrock"
    },
    {
      "x": -8,
      "y": 1,
      "z": -18,
      "name": "Rock_Bedrock"
    },
    {
      "x": -8,
      "y": 2,
      "z": -18,
      "name": "Rock_Bedrock"
    },
    {
      "x": -8,
      "y": 3,
      "z": -18,
      "name": "Rock_Bedrock"
    },
    {
      "x": -8,
      "y": 0,
      "z": 20,
      "name": "Rock_Bedrock"
    },
    {
      "x": -8,
      "y": 1,
      "z": 20,
      "name": "Rock_Bedrock"
    },
    {
      "x": -8,
      "y": 2,
      "z": 20,
      "name": "Rock_Bedrock"
    },
    {
      "x": -8,
      "y": 3,
      "z": 20,
      "name": "Rock_Bedrock"
    },
    {
      "x": -8,
      "y": 0,
      "z": 21,
      "name": "Soil_Hive_Corrupted_Brick",
      "rotation": 1
    },
    {
      "x": -8,
      "y": 1,
      "z": 21,
      "name": "Soil_Hive_Corrupted_Brick",
      "rotation": 1
    },
    {
      "x": -8,
      "y": 2,
      "z": 21,
      "name": "Soil_Hive_Corrupted_Brick",
      "rotation": 1
    },
    {
      "x": -8,
      "y": 3,
      "z": 21,
      "name": "Soil_Hive_Corrupted_Brick",
      "rotation": 1
    },
    {
      "x": -7,
      "y": 0,
      "z": -19,
      "name": "Soil_Hive_Corrupted_Brick",
      "rotation": 1
    },
    {
      "x": -7,
      "y": 1,
      "z": -19,
      "name": "Soil_Hive_Corrupted_Brick",
      "rotation": 1
    },
    {
      "x": -7,
      "y": 2,
      "z": -19,
      "name": "Soil_Hive_Corrupted_Brick",
      "rotation": 1
    },
    {
      "x": -7,
      "y": 3,
      "z": -19,
      "name": "Soil_Hive_Corrupted_Brick",
      "rotation": 1
    },
    {
      "x": -7,
      "y": 0,
      "z": -18,
      "name": "Rock_Bedrock"
    },
    {
      "x": -7,
      "y": 1,
      "z": -18,
      "name": "Rock_Bedrock"
    },
    {
      "x": -7,
      "y": 2,
      "z": -18,
      "name": "Rock_Bedrock"
    },
    {
      "x": -7,
      "y": 3,
      "z": -18,
      "name": "Rock_Bedrock"
    },
    {
      "x": -7,
      "y": 0,
      "z": 20,
      "name": "Rock_Bedrock"
    },
    {
      "x": -7,
      "y": 1,
      "z": 20,
      "name": "Rock_Bedrock"
    },
    {
      "x": -7,
      "y": 2,
      "z": 20,
      "name": "Rock_Bedrock"
    },
    {
      "x": -7,
      "y": 3,
      "z": 20,
      "name": "Rock_Bedrock"
    },
    {
      "x": -6,
      "y": 0,
      "z": -19,
      "name": "Soil_Hive_Corrupted_Brick",
      "rotation": 1
    },
    {
      "x": -6,
      "y": 1,
      "z": -19,
      "name": "Soil_Hive_Corrupted_Brick",
      "rotation": 1
    },
    {
      "x": -6,
      "y": 2,
      "z": -19,
      "name": "Soil_Hive_Corrupted_Brick",
      "rotation": 1
    },
    {
      "x": -6,
      "y": 3,
      "z": -19,
      "name": "Soil_Hive_Corrupted_Brick",
      "rotation": 1
    },
    {
      "x": -6,
      "y": 0,
      "z": -18,
      "name": "Rock_Bedrock"
    },
    {
      "x": -6,
      "y": 1,
      "z": -18,
      "name": "Rock_Bedrock"
    },
    {
      "x": -6,
      "y": 2,
      "z": -18,
      "name": "Rock_Bedrock"
    },
    {
      "x": -6,
      "y": 3,
      "z": -18,
      "name": "Rock_Bedrock"
    },
    {
      "x": -6,
      "y": 0,
      "z": 20,
      "name": "Rock_Bedrock"
    },
    {
      "x": -6,
      "y": 1,
      "z": 20,
      "name": "Rock_Bedrock"
    },
    {
      "x": -6,
      "y": 2,
      "z": 20,
      "name": "Rock_Bedrock"
    },
    {
      "x": -6,
      "y": 3,
      "z": 20,
      "name": "Rock_Bedrock"
    },
    {
      "x": -5,
      "y": 0,
      "z": -18,
      "name": "Rock_Bedrock"
    },
    {
      "x": -5,
      "y": 1,
      "z": -18,
      "name": "Rock_Bedrock"
    },
    {
      "x": -5,
      "y": 2,
      "z": -18,
      "name": "Rock_Bedrock"
    },
    {
      "x": -5,
      "y": 3,
      "z": -18,
      "name": "Rock_Bedrock"
    },
    {
      "x": -5,
      "y": 0,
      "z": -1,
      "name": "Rock_Bedrock"
    },
    {
      "x": -5,
      "y": 0,
      "z": 3,
      "name": "Rock_Bedrock"
    },
    {
      "x": -5,
      "y": 0,
      "z": 20,
      "name": "Rock_Bedrock"
    },
    {
      "x": -5,
      "y": 1,
      "z": 20,
      "name": "Rock_Bedrock"
    },
    {
      "x": -5,
      "y": 2,
      "z": 20,
      "name": "Rock_Bedrock"
    },
    {
      "x": -5,
      "y": 3,
      "z": 20,
      "name": "Rock_Bedrock"
    },
    {
      "x": -5,
      "y": 0,
      "z": 21,
      "name": "Soil_Hive_Corrupted_Brick",
      "rotation": 1
    },
    {
      "x": -5,
      "y": 1,
      "z": 21,
      "name": "Soil_Hive_Corrupted_Brick",
      "rotation": 1
    },
    {
      "x": -5,
      "y": 2,
      "z": 21,
      "name": "Soil_Hive_Corrupted_Brick",
      "rotation": 1
    },
    {
      "x": -5,
      "y": 3,
      "z": 21,
      "name": "Soil_Hive_Corrupted_Brick",
      "rotation": 1
    },
    {
      "x": -4,
      "y": 0,
      "z": -18,
      "name": "Rock_Bedrock"
    },
    {
      "x": -4,
      "y": 1,
      "z": -18,
      "name": "Rock_Bedrock"
    },
    {
      "x": -4,
      "y": 2,
      "z": -18,
      "name": "Rock_Bedrock"
    },
    {
      "x": -4,
      "y": 3,
      "z": -18,
      "name": "Rock_Bedrock"
    },
    {
      "x": -4,
      "y": 0,
      "z": -1,
      "name": "Rock_Bedrock"
    },
    {
      "x": -4,
      "y": 0,
      "z": 3,
      "name": "Rock_Bedrock"
    },
    {
      "x": -4,
      "y": 0,
      "z": 20,
      "name": "Rock_Bedrock"
    },
    {
      "x": -4,
      "y": 1,
      "z": 20,
      "name": "Rock_Bedrock"
    },
    {
      "x": -4,
      "y": 2,
      "z": 20,
      "name": "Rock_Bedrock"
    },
    {
      "x": -4,
      "y": 3,
      "z": 20,
      "name": "Rock_Bedrock"
    },
    {
      "x": -4,
      "y": 0,
      "z": 21,
      "name": "Soil_Hive_Corrupted_Brick",
      "rotation": 1
    },
    {
      "x": -4,
      "y": 1,
      "z": 21,
      "name": "Soil_Hive_Corrupted_Brick",
      "rotation": 1
    },
    {
      "x": -4,
      "y": 2,
      "z": 21,
      "name": "Soil_Hive_Corrupted_Brick",
      "rotation": 1
    },
    {
      "x": -4,
      "y": 3,
      "z": 21,
      "name": "Soil_Hive_Corrupted_Brick",
      "rotation": 1
    },
    {
      "x": -3,
      "y": 0,
      "z": -19,
      "name": "Soil_Hive_Corrupted_Brick",
      "rotation": 3
    },
    {
      "x": -3,
      "y": 1,
      "z": -19,
      "name": "Soil_Hive_Corrupted_Brick",
      "rotation": 3
    },
    {
      "x": -3,
      "y": 2,
      "z": -19,
      "name": "Soil_Hive_Corrupted_Brick",
      "rotation": 3
    },
    {
      "x": -3,
      "y": 3,
      "z": -19,
      "name": "Soil_Hive_Corrupted_Brick",
      "rotation": 3
    },
    {
      "x": -3,
      "y": 0,
      "z": -18,
      "name": "Rock_Bedrock"
    },
    {
      "x": -3,
      "y": 1,
      "z": -18,
      "name": "Rock_Bedrock"
    },
    {
      "x": -3,
      "y": 2,
      "z": -18,
      "name": "Rock_Bedrock"
    },
    {
      "x": -3,
      "y": 3,
      "z": -18,
      "name": "Rock_Bedrock"
    },
    {
      "x": -3,
      "y": 0,
      "z": -1,
      "name": "Rock_Bedrock"
    },
    {
      "x": -3,
      "y": 0,
      "z": 3,
      "name": "Rock_Bedrock"
    },
    {
      "x": -3,
      "y": 0,
      "z": 20,
      "name": "Rock_Bedrock"
    },
    {
      "x": -3,
      "y": 1,
      "z": 20,
      "name": "Rock_Bedrock"
    },
    {
      "x": -3,
      "y": 2,
      "z": 20,
      "name": "Rock_Bedrock"
    },
    {
      "x": -3,
      "y": 3,
      "z": 20,
      "name": "Rock_Bedrock"
    },
    {
      "x": -3,
      "y": 0,
      "z": 21,
      "name": "Soil_Hive_Corrupted_Brick",
      "rotation": 1
    },
    {
      "x": -3,
      "y": 1,
      "z": 21,
      "name": "Soil_Hive_Corrupted_Brick",
      "rotation": 1
    },
    {
      "x": -3,
      "y": 2,
      "z": 21,
      "name": "Soil_Hive_Corrupted_Brick",
      "rotation": 1
    },
    {
      "x": -3,
      "y": 3,
      "z": 21,
      "name": "Soil_Hive_Corrupted_Brick",
      "rotation": 1
    },
    {
      "x": -2,
      "y": 0,
      "z": -19,
      "name": "Soil_Hive_Corrupted_Brick",
      "rotation": 3
    },
    {
      "x": -2,
      "y": 1,
      "z": -19,
      "name": "Soil_Hive_Corrupted_Brick",
      "rotation": 3
    },
    {
      "x": -2,
      "y": 2,
      "z": -19,
      "name": "Soil_Hive_Corrupted_Brick",
      "rotation": 3
    },
    {
      "x": -2,
      "y": 3,
      "z": -19,
      "name": "Soil_Hive_Corrupted_Brick",
      "rotation": 3
    },
    {
      "x": -2,
      "y": 0,
      "z": -18,
      "name": "Rock_Bedrock"
    },
    {
      "x": -2,
      "y": 1,
      "z": -18,
      "name": "Rock_Bedrock"
    },
    {
      "x": -2,
      "y": 2,
      "z": -18,
      "name": "Rock_Bedrock"
    },
    {
      "x": -2,
      "y": 3,
      "z": -18,
      "name": "Rock_Bedrock"
    },
    {
      "x": -2,
      "y": 0,
      "z": -2,
      "name": "Rock_Bedrock"
    },
    {
      "x": -2,
      "y": 0,
      "z": -1,
      "name": "Rock_Bedrock"
    },
    {
      "x": -2,
      "y": 0,
      "z": 0,
      "name": "Rock_Bedrock"
    },
    {
      "x": -2,
      "y": 0,
      "z": 1,
      "name": "Rock_Bedrock"
    },
    {
      "x": -2,
      "y": 0,
      "z": 2,
      "name": "Rock_Bedrock"
    },
    {
      "x": -2,
      "y": 0,
      "z": 3,
      "name": "Rock_Bedrock"
    },
    {
      "x": -2,
      "y": 0,
      "z": 4,
      "name": "Rock_Bedrock"
    },
    {
      "x": -2,
      "y": 0,
      "z": 20,
      "name": "Rock_Bedrock"
    },
    {
      "x": -2,
      "y": 1,
      "z": 20,
      "name": "Rock_Bedrock"
    },
    {
      "x": -2,
      "y": 2,
      "z": 20,
      "name": "Rock_Bedrock"
    },
    {
      "x": -2,
      "y": 3,
      "z": 20,
      "name": "Rock_Bedrock"
    },
    {
      "x": -1,
      "y": 0,
      "z": -19,
      "name": "Soil_Hive_Corrupted_Brick",
      "rotation": 3
    },
    {
      "x": -1,
      "y": 1,
      "z": -19,
      "name": "Soil_Hive_Corrupted_Brick",
      "rotation": 3
    },
    {
      "x": -1,
      "y": 2,
      "z": -19,
      "name": "Soil_Hive_Corrupted_Brick",
      "rotation": 3
    },
    {
      "x": -1,
      "y": 3,
      "z": -19,
      "name": "Soil_Hive_Corrupted_Brick",
      "rotation": 3
    },
    {
      "x": -1,
      "y": 0,
      "z": -18,
      "name": "Rock_Bedrock"
    },
    {
      "x": -1,
      "y": 1,
      "z": -18,
      "name": "Rock_Bedrock"
    },
    {
      "x": -1,
      "y": 2,
      "z": -18,
      "name": "Rock_Bedrock"
    },
    {
      "x": -1,
      "y": 3,
      "z": -18,
      "name": "Rock_Bedrock"
    },
    {
      "x": -1,
      "y": 0,
      "z": -5,
      "name": "Rock_Bedrock"
    },
    {
      "x": -1,
      "y": 0,
      "z": -4,
      "name": "Rock_Bedrock"
    },
    {
      "x": -1,
      "y": 0,
      "z": -3,
      "name": "Rock_Bedrock"
    },
    {
      "x": -1,
      "y": 0,
      "z": -2,
      "name": "Rock_Bedrock"
    },
    {
      "x": -1,
      "y": 0,
      "z": -1,
      "name": "Rock_Bedrock"
    },
    {
      "x": -1,
      "y": 0,
      "z": 0,
      "name": "Rock_Bedrock"
    },
    {
      "x": -1,
      "y": 0,
      "z": 1,
      "name": "Rock_Bedrock"
    },
    {
      "x": -1,
      "y": 0,
      "z": 2,
      "name": "Rock_Bedrock"
    },
    {
      "x": -1,
      "y": 0,
      "z": 3,
      "name": "Rock_Bedrock"
    },
    {
      "x": -1,
      "y": 0,
      "z": 4,
      "name": "Rock_Bedrock"
    },
    {
      "x": -1,
      "y": 0,
      "z": 5,
      "name": "Rock_Bedrock"
    },
    {
      "x": -1,
      "y": 0,
      "z": 6,
      "name": "Rock_Bedrock"
    },
    {
      "x": -1,
      "y": 0,
      "z": 7,
      "name": "Rock_Bedrock"
    },
    {
      "x": -1,
      "y": 0,
      "z": 20,
      "name": "Rock_Bedrock"
    },
    {
      "x": -1,
      "y": 1,
      "z": 20,
      "name": "Rock_Bedrock"
    },
    {
      "x": -1,
      "y": 2,
      "z": 20,
      "name": "Rock_Bedrock"
    },
    {
      "x": -1,
      "y": 3,
      "z": 20,
      "name": "Rock_Bedrock"
    },
    {
      "x": -1,
      "y": 0,
      "z": 21,
      "name": "Soil_Hive_Corrupted_Brick",
      "rotation": 3
    },
    {
      "x": -1,
      "y": 1,
      "z": 21,
      "name": "Soil_Hive_Corrupted_Brick",
      "rotation": 3
    },
    {
      "x": -1,
      "y": 2,
      "z": 21,
      "name": "Soil_Hive_Corrupted_Brick",
      "rotation": 3
    },
    {
      "x": -1,
      "y": 3,
      "z": 21,
      "name": "Soil_Hive_Corrupted_Brick",
      "rotation": 3
    },
    {
      "x": 0,
      "y": 0,
      "z": -18,
      "name": "Rock_Bedrock"
    },
    {
      "x": 0,
      "y": 1,
      "z": -18,
      "name": "Rock_Bedrock"
    },
    {
      "x": 0,
      "y": 2,
      "z": -18,
      "name": "Rock_Bedrock"
    },
    {
      "x": 0,
      "y": 3,
      "z": -18,
      "name": "Rock_Bedrock"
    },
    {
      "x": 0,
      "y": 0,
      "z": -2,
      "name": "Rock_Bedrock"
    },
    {
      "x": 0,
      "y": 0,
      "z": -1,
      "name": "Rock_Bedrock"
    },
    {
      "x": 0,
      "y": 0,
      "z": 0,
      "name": "Rock_Bedrock"
    },
    {
      "x": 0,
      "y": 0,
      "z": 1,
      "name": "Rock_Bedrock"
    },
    {
      "x": 0,
      "y": 0,
      "z": 2,
      "name": "Rock_Bedrock"
    },
    {
      "x": 0,
      "y": 0,
      "z": 3,
      "name": "Rock_Bedrock"
    },
    {
      "x": 0,
      "y": 0,
      "z": 4,
      "name": "Rock_Bedrock"
    },
    {
      "x": 0,
      "y": 0,
      "z": 20,
      "name": "Rock_Bedrock"
    },
    {
      "x": 0,
      "y": 1,
      "z": 20,
      "name": "Rock_Bedrock"
    },
    {
      "x": 0,
      "y": 2,
      "z": 20,
      "name": "Rock_Bedrock"
    },
    {
      "x": 0,
      "y": 3,
      "z": 20,
      "name": "Rock_Bedrock"
    },
    {
      "x": 0,
      "y": 0,
      "z": 21,
      "name": "Soil_Hive_Corrupted_Brick",
      "rotation": 3
    },
    {
      "x": 0,
      "y": 1,
      "z": 21,
      "name": "Soil_Hive_Corrupted_Brick",
      "rotation": 3
    },
    {
      "x": 0,
      "y": 2,
      "z": 21,
      "name": "Soil_Hive_Corrupted_Brick",
      "rotation": 3
    },
    {
      "x": 0,
      "y": 3,
      "z": 21,
      "name": "Soil_Hive_Corrupted_Brick",
      "rotation": 3
    },
    {
      "x": 1,
      "y": 0,
      "z": -19,
      "name": "Soil_Hive_Corrupted_Brick",
      "rotation": 1
    },
    {
      "x": 1,
      "y": 1,
      "z": -19,
      "name": "Soil_Hive_Corrupted_Brick",
      "rotation": 1
    },
    {
      "x": 1,
      "y": 2,
      "z": -19,
      "name": "Soil_Hive_Corrupted_Brick",
      "rotation": 1
    },
    {
      "x": 1,
      "y": 3,
      "z": -19,
      "name": "Soil_Hive_Corrupted_Brick",
      "rotation": 1
    },
    {
      "x": 1,
      "y": 0,
      "z": -18,
      "name": "Rock_Bedrock"
    },
    {
      "x": 1,
      "y": 1,
      "z": -18,
      "name": "Rock_Bedrock"
    },
    {
      "x": 1,
      "y": 2,
      "z": -18,
      "name": "Rock_Bedrock"
    },
    {
      "x": 1,
      "y": 3,
      "z": -18,
      "name": "Rock_Bedrock"
    },
    {
      "x": 1,
      "y": 0,
      "z": -2,
      "name": "Rock_Bedrock"
    },
    {
      "x": 1,
      "y": 0,
      "z": -1,
      "name": "Rock_Bedrock"
    },
    {
      "x": 1,
      "y": 0,
      "z": 0,
      "name": "Rock_Bedrock"
    },
    {
      "x": 1,
      "y": 0,
      "z": 1,
      "name": "Rock_Bedrock"
    },
    {
      "x": 1,
      "y": 0,
      "z": 2,
      "name": "Rock_Bedrock"
    },
    {
      "x": 1,
      "y": 0,
      "z": 3,
      "name": "Rock_Bedrock"
    },
    {
      "x": 1,
      "y": 0,
      "z": 4,
      "name": "Rock_Bedrock"
    },
    {
      "x": 1,
      "y": 0,
      "z": 20,
      "name": "Rock_Bedrock"
    },
    {
      "x": 1,
      "y": 1,
      "z": 20,
      "name": "Rock_Bedrock"
    },
    {
      "x": 1,
      "y": 2,
      "z": 20,
      "name": "Rock_Bedrock"
    },
    {
      "x": 1,
      "y": 3,
      "z": 20,
      "name": "Rock_Bedrock"
    },
    {
      "x": 1,
      "y": 0,
      "z": 21,
      "name": "Soil_Hive_Corrupted_Brick",
      "rotation": 3
    },
    {
      "x": 1,
      "y": 1,
      "z": 21,
      "name": "Soil_Hive_Corrupted_Brick",
      "rotation": 3
    },
    {
      "x": 1,
      "y": 2,
      "z": 21,
      "name": "Soil_Hive_Corrupted_Brick",
      "rotation": 3
    },
    {
      "x": 1,
      "y": 3,
      "z": 21,
      "name": "Soil_Hive_Corrupted_Brick",
      "rotation": 3
    },
    {
      "x": 2,
      "y": 0,
      "z": -19,
      "name": "Soil_Hive_Corrupted_Brick",
      "rotation": 1
    },
    {
      "x": 2,
      "y": 1,
      "z": -19,
      "name": "Soil_Hive_Corrupted_Brick",
      "rotation": 1
    },
    {
      "x": 2,
      "y": 2,
      "z": -19,
      "name": "Soil_Hive_Corrupted_Brick",
      "rotation": 1
    },
    {
      "x": 2,
      "y": 3,
      "z": -19,
      "name": "Soil_Hive_Corrupted_Brick",
      "rotation": 1
    },
    {
      "x": 2,
      "y": 0,
      "z": -18,
      "name": "Rock_Bedrock"
    },
    {
      "x": 2,
      "y": 1,
      "z": -18,
      "name": "Rock_Bedrock"
    },
    {
      "x": 2,
      "y": 2,
      "z": -18,
      "name": "Rock_Bedrock"
    },
    {
      "x": 2,
      "y": 3,
      "z": -18,
      "name": "Rock_Bedrock"
    },
    {
      "x": 2,
      "y": 0,
      "z": -2,
      "name": "Rock_Bedrock"
    },
    {
      "x": 2,
      "y": 0,
      "z": -1,
      "name": "Rock_Bedrock"
    },
    {
      "x": 2,
      "y": 0,
      "z": 0,
      "name": "Rock_Bedrock"
    },
    {
      "x": 2,
      "y": 0,
      "z": 1,
      "name": "Rock_Bedrock"
    },
    {
      "x": 2,
      "y": 0,
      "z": 2,
      "name": "Rock_Bedrock"
    },
    {
      "x": 2,
      "y": 0,
      "z": 3,
      "name": "Rock_Bedrock"
    },
    {
      "x": 2,
      "y": 0,
      "z": 4,
      "name": "Rock_Bedrock"
    },
    {
      "x": 2,
      "y": 0,
      "z": 20,
      "name": "Rock_Bedrock"
    },
    {
      "x": 2,
      "y": 1,
      "z": 20,
      "name": "Rock_Bedrock"
    },
    {
      "x": 2,
      "y": 2,
      "z": 20,
      "name": "Rock_Bedrock"
    },
    {
      "x": 2,
      "y": 3,
      "z": 20,
      "name": "Rock_Bedrock"
    },
    {
      "x": 3,
      "y": 0,
      "z": -19,
      "name": "Soil_Hive_Corrupted_Brick",
      "rotation": 1
    },
    {
      "x": 3,
      "y": 1,
      "z": -19,
      "name": "Soil_Hive_Corrupted_Brick",
      "rotation": 1
    },
    {
      "x": 3,
      "y": 2,
      "z": -19,
      "name": "Soil_Hive_Corrupted_Brick",
      "rotation": 1
    },
    {
      "x": 3,
      "y": 3,
      "z": -19,
      "name": "Soil_Hive_Corrupted_Brick",
      "rotation": 1
    },
    {
      "x": 3,
      "y": 0,
      "z": -18,
      "name": "Rock_Bedrock"
    },
    {
      "x": 3,
      "y": 1,
      "z": -18,
      "name": "Rock_Bedrock"
    },
    {
      "x": 3,
      "y": 2,
      "z": -18,
      "name": "Rock_Bedrock"
    },
    {
      "x": 3,
      "y": 3,
      "z": -18,
      "name": "Rock_Bedrock"
    },
    {
      "x": 3,
      "y": 0,
      "z": -5,
      "name": "Rock_Bedrock"
    },
    {
      "x": 3,
      "y": 0,
      "z": -4,
      "name": "Rock_Bedrock"
    },
    {
      "x": 3,
      "y": 0,
      "z": -3,
      "name": "Rock_Bedrock"
    },
    {
      "x": 3,
      "y": 0,
      "z": -2,
      "name": "Rock_Bedrock"
    },
    {
      "x": 3,
      "y": 0,
      "z": -1,
      "name": "Rock_Bedrock"
    },
    {
      "x": 3,
      "y": 0,
      "z": 0,
      "name": "Rock_Bedrock"
    },
    {
      "x": 3,
      "y": 0,
      "z": 1,
      "name": "Rock_Bedrock"
    },
    {
      "x": 3,
      "y": 0,
      "z": 2,
      "name": "Rock_Bedrock"
    },
    {
      "x": 3,
      "y": 0,
      "z": 3,
      "name": "Rock_Bedrock"
    },
    {
      "x": 3,
      "y": 0,
      "z": 4,
      "name": "Rock_Bedrock"
    },
    {
      "x": 3,
      "y": 0,
      "z": 5,
      "name": "Rock_Bedrock"
    },
    {
      "x": 3,
      "y": 0,
      "z": 6,
      "name": "Rock_Bedrock"
    },
    {
      "x": 3,
      "y": 0,
      "z": 7,
      "name": "Rock_Bedrock"
    },
    {
      "x": 3,
      "y": 0,
      "z": 20,
      "name": "Rock_Bedrock"
    },
    {
      "x": 3,
      "y": 1,
      "z": 20,
      "name": "Rock_Bedrock"
    },
    {
      "x": 3,
      "y": 2,
      "z": 20,
      "name": "Rock_Bedrock"
    },
    {
      "x": 3,
      "y": 3,
      "z": 20,
      "name": "Rock_Bedrock"
    },
    {
      "x": 3,
      "y": 0,
      "z": 21,
      "name": "Soil_Hive_Corrupted_Brick",
      "rotation": 1
    },
    {
      "x": 3,
      "y": 1,
      "z": 21,
      "name": "Soil_Hive_Corrupted_Brick",
      "rotation": 1
    },
    {
      "x": 3,
      "y": 2,
      "z": 21,
      "name": "Soil_Hive_Corrupted_Brick",
      "rotation": 1
    },
    {
      "x": 3,
      "y": 3,
      "z": 21,
      "name": "Soil_Hive_Corrupted_Brick",
      "rotation": 1
    },
    {
      "x": 4,
      "y": 0,
      "z": -18,
      "name": "Rock_Bedrock"
    },
    {
      "x": 4,
      "y": 1,
      "z": -18,
      "name": "Rock_Bedrock"
    },
    {
      "x": 4,
      "y": 2,
      "z": -18,
      "name": "Rock_Bedrock"
    },
    {
      "x": 4,
      "y": 3,
      "z": -18,
      "name": "Rock_Bedrock"
    },
    {
      "x": 4,
      "y": 0,
      "z": -2,
      "name": "Rock_Bedrock"
    },
    {
      "x": 4,
      "y": 0,
      "z": -1,
      "name": "Rock_Bedrock"
    },
    {
      "x": 4,
      "y": 0,
      "z": 0,
      "name": "Rock_Bedrock"
    },
    {
      "x": 4,
      "y": 0,
      "z": 1,
      "name": "Rock_Bedrock"
    },
    {
      "x": 4,
      "y": 0,
      "z": 2,
      "name": "Rock_Bedrock"
    },
    {
      "x": 4,
      "y": 0,
      "z": 3,
      "name": "Rock_Bedrock"
    },
    {
      "x": 4,
      "y": 0,
      "z": 4,
      "name": "Rock_Bedrock"
    },
    {
      "x": 4,
      "y": 0,
      "z": 20,
      "name": "Rock_Bedrock"
    },
    {
      "x": 4,
      "y": 1,
      "z": 20,
      "name": "Rock_Bedrock"
    },
    {
      "x": 4,
      "y": 2,
      "z": 20,
      "name": "Rock_Bedrock"
    },
    {
      "x": 4,
      "y": 3,
      "z": 20,
      "name": "Rock_Bedrock"
    },
    {
      "x": 4,
      "y": 0,
      "z": 21,
      "name": "Soil_Hive_Corrupted_Brick",
      "rotation": 1
    },
    {
      "x": 4,
      "y": 1,
      "z": 21,
      "name": "Soil_Hive_Corrupted_Brick",
      "rotation": 1
    },
    {
      "x": 4,
      "y": 2,
      "z": 21,
      "name": "Soil_Hive_Corrupted_Brick",
      "rotation": 1
    },
    {
      "x": 4,
      "y": 3,
      "z": 21,
      "name": "Soil_Hive_Corrupted_Brick",
      "rotation": 1
    },
    {
      "x": 5,
      "y": 0,
      "z": -19,
      "name": "Soil_Hive_Corrupted_Brick",
      "rotation": 3
    },
    {
      "x": 5,
      "y": 1,
      "z": -19,
      "name": "Soil_Hive_Corrupted_Brick",
      "rotation": 3
    },
    {
      "x": 5,
      "y": 2,
      "z": -19,
      "name": "Soil_Hive_Corrupted_Brick",
      "rotation": 3
    },
    {
      "x": 5,
      "y": 3,
      "z": -19,
      "name": "Soil_Hive_Corrupted_Brick",
      "rotation": 3
    },
    {
      "x": 5,
      "y": 0,
      "z": -18,
      "name": "Rock_Bedrock"
    },
    {
      "x": 5,
      "y": 1,
      "z": -18,
      "name": "Rock_Bedrock"
    },
    {
      "x": 5,
      "y": 2,
      "z": -18,
      "name": "Rock_Bedrock"
    },
    {
      "x": 5,
      "y": 3,
      "z": -18,
      "name": "Rock_Bedrock"
    },
    {
      "x": 5,
      "y": 0,
      "z": -1,
      "name": "Rock_Bedrock"
    },
    {
      "x": 5,
      "y": 0,
      "z": 3,
      "name": "Rock_Bedrock"
    },
    {
      "x": 5,
      "y": 0,
      "z": 20,
      "name": "Rock_Bedrock"
    },
    {
      "x": 5,
      "y": 1,
      "z": 20,
      "name": "Rock_Bedrock"
    },
    {
      "x": 5,
      "y": 2,
      "z": 20,
      "name": "Rock_Bedrock"
    },
    {
      "x": 5,
      "y": 3,
      "z": 20,
      "name": "Rock_Bedrock"
    },
    {
      "x": 5,
      "y": 0,
      "z": 21,
      "name": "Soil_Hive_Corrupted_Brick",
      "rotation": 1
    },
    {
      "x": 5,
      "y": 1,
      "z": 21,
      "name": "Soil_Hive_Corrupted_Brick",
      "rotation": 1
    },
    {
      "x": 5,
      "y": 2,
      "z": 21,
      "name": "Soil_Hive_Corrupted_Brick",
      "rotation": 1
    },
    {
      "x": 5,
      "y": 3,
      "z": 21,
      "name": "Soil_Hive_Corrupted_Brick",
      "rotation": 1
    },
    {
      "x": 6,
      "y": 0,
      "z": -19,
      "name": "Soil_Hive_Corrupted_Brick",
      "rotation": 3
    },
    {
      "x": 6,
      "y": 1,
      "z": -19,
      "name": "Soil_Hive_Corrupted_Brick",
      "rotation": 3
    },
    {
      "x": 6,
      "y": 2,
      "z": -19,
      "name": "Soil_Hive_Corrupted_Brick",
      "rotation": 3
    },
    {
      "x": 6,
      "y": 3,
      "z": -19,
      "name": "Soil_Hive_Corrupted_Brick",
      "rotation": 3
    },
    {
      "x": 6,
      "y": 0,
      "z": -18,
      "name": "Rock_Bedrock"
    },
    {
      "x": 6,
      "y": 1,
      "z": -18,
      "name": "Rock_Bedrock"
    },
    {
      "x": 6,
      "y": 2,
      "z": -18,
      "name": "Rock_Bedrock"
    },
    {
      "x": 6,
      "y": 3,
      "z": -18,
      "name": "Rock_Bedrock"
    },
    {
      "x": 6,
      "y": 0,
      "z": -1,
      "name": "Rock_Bedrock"
    },
    {
      "x": 6,
      "y": 0,
      "z": 3,
      "name": "Rock_Bedrock"
    },
    {
      "x": 6,
      "y": 0,
      "z": 20,
      "name": "Rock_Bedrock"
    },
    {
      "x": 6,
      "y": 1,
      "z": 20,
      "name": "Rock_Bedrock"
    },
    {
      "x": 6,
      "y": 2,
      "z": 20,
      "name": "Rock_Bedrock"
    },
    {
      "x": 6,
      "y": 3,
      "z": 20,
      "name": "Rock_Bedrock"
    },
    {
      "x": 7,
      "y": 0,
      "z": -19,
      "name": "Soil_Hive_Corrupted_Brick",
      "rotation": 3
    },
    {
      "x": 7,
      "y": 1,
      "z": -19,
      "name": "Soil_Hive_Corrupted_Brick",
      "rotation": 3
    },
    {
      "x": 7,
      "y": 2,
      "z": -19,
      "name": "Soil_Hive_Corrupted_Brick",
      "rotation": 3
    },
    {
      "x": 7,
      "y": 3,
      "z": -19,
      "name": "Soil_Hive_Corrupted_Brick",
      "rotation": 3
    },
    {
      "x": 7,
      "y": 0,
      "z": -18,
      "name": "Rock_Bedrock"
    },
    {
      "x": 7,
      "y": 1,
      "z": -18,
      "name": "Rock_Bedrock"
    },
    {
      "x": 7,
      "y": 2,
      "z": -18,
      "name": "Rock_Bedrock"
    },
    {
      "x": 7,
      "y": 3,
      "z": -18,
      "name": "Rock_Bedrock"
    },
    {
      "x": 7,
      "y": 0,
      "z": -1,
      "name": "Rock_Bedrock"
    },
    {
      "x": 7,
      "y": 0,
      "z": 3,
      "name": "Rock_Bedrock"
    },
    {
      "x": 7,
      "y": 0,
      "z": 20,
      "name": "Rock_Bedrock"
    },
    {
      "x": 7,
      "y": 1,
      "z": 20,
      "name": "Rock_Bedrock"
    },
    {
      "x": 7,
      "y": 2,
      "z": 20,
      "name": "Rock_Bedrock"
    },
    {
      "x": 7,
      "y": 3,
      "z": 20,
      "name": "Rock_Bedrock"
    },
    {
      "x": 8,
      "y": 0,
      "z": -18,
      "name": "Rock_Bedrock"
    },
    {
      "x": 8,
      "y": 1,
      "z": -18,
      "name": "Rock_Bedrock"
    },
    {
      "x": 8,
      "y": 2,
      "z": -18,
      "name": "Rock_Bedrock"
    },
    {
      "x": 8,
      "y": 3,
      "z": -18,
      "name": "Rock_Bedrock"
    },
    {
      "x": 8,
      "y": 0,
      "z": 20,
      "name": "Rock_Bedrock"
    },
    {
      "x": 8,
      "y": 1,
      "z": 20,
      "name": "Rock_Bedrock"
    },
    {
      "x": 8,
      "y": 2,
      "z": 20,
      "name": "Rock_Bedrock"
    },
    {
      "x": 8,
      "y": 3,
      "z": 20,
      "name": "Rock_Bedrock"
    },
    {
      "x": 8,
      "y": 0,
      "z": 21,
      "name": "Soil_Hive_Corrupted_Brick",
      "rotation": 3
    },
    {
      "x": 8,
      "y": 1,
      "z": 21,
      "name": "Soil_Hive_Corrupted_Brick",
      "rotation": 3
    },
    {
      "x": 8,
      "y": 2,
      "z": 21,
      "name": "Soil_Hive_Corrupted_Brick",
      "rotation": 3
    },
    {
      "x": 8,
      "y": 3,
      "z": 21,
      "name": "Soil_Hive_Corrupted_Brick",
      "rotation": 3
    },
    {
      "x": 9,
      "y": 0,
      "z": -18,
      "name": "Rock_Bedrock"
    },
    {
      "x": 9,
      "y": 1,
      "z": -18,
      "name": "Rock_Bedrock"
    },
    {
      "x": 9,
      "y": 2,
      "z": -18,
      "name": "Rock_Bedrock"
    },
    {
      "x": 9,
      "y": 3,
      "z": -18,
      "name": "Rock_Bedrock"
    },
    {
      "x": 9,
      "y": 0,
      "z": 20,
      "name": "Rock_Bedrock"
    },
    {
      "x": 9,
      "y": 1,
      "z": 20,
      "name": "Rock_Bedrock"
    },
    {
      "x": 9,
      "y": 2,
      "z": 20,
      "name": "Rock_Bedrock"
    },
    {
      "x": 9,
      "y": 3,
      "z": 20,
      "name": "Rock_Bedrock"
    },
    {
      "x": 9,
      "y": 0,
      "z": 21,
      "name": "Soil_Hive_Corrupted_Brick",
      "rotation": 3
    },
    {
      "x": 9,
      "y": 1,
      "z": 21,
      "name": "Soil_Hive_Corrupted_Brick",
      "rotation": 3
    },
    {
      "x": 9,
      "y": 2,
      "z": 21,
      "name": "Soil_Hive_Corrupted_Brick",
      "rotation": 3
    },
    {
      "x": 9,
      "y": 3,
      "z": 21,
      "name": "Soil_Hive_Corrupted_Brick",
      "rotation": 3
    },
    {
      "x": 10,
      "y": 0,
      "z": -19,
      "name": "Soil_Hive_Corrupted_Brick",
      "rotation": 3
    },
    {
      "x": 10,
      "y": 1,
      "z": -19,
      "name": "Soil_Hive_Corrupted_Brick",
      "rotation": 3
    },
    {
      "x": 10,
      "y": 2,
      "z": -19,
      "name": "Soil_Hive_Corrupted_Brick",
      "rotation": 3
    },
    {
      "x": 10,
      "y": 3,
      "z": -19,
      "name": "Soil_Hive_Corrupted_Brick",
      "rotation": 3
    },
    {
      "x": 10,
      "y": 0,
      "z": -18,
      "name": "Rock_Bedrock"
    },
    {
      "x": 10,
      "y": 1,
      "z": -18,
      "name": "Rock_Bedrock"
    },
    {
      "x": 10,
      "y": 2,
      "z": -18,
      "name": "Rock_Bedrock"
    },
    {
      "x": 10,
      "y": 3,
      "z": -18,
      "name": "Rock_Bedrock"
    },
    {
      "x": 10,
      "y": 0,
      "z": 20,
      "name": "Rock_Bedrock"
    },
    {
      "x": 10,
      "y": 1,
      "z": 20,
      "name": "Rock_Bedrock"
    },
    {
      "x": 10,
      "y": 2,
      "z": 20,
      "name": "Rock_Bedrock"
    },
    {
      "x": 10,
      "y": 3,
      "z": 20,
      "name": "Rock_Bedrock"
    },
    {
      "x": 10,
      "y": 0,
      "z": 21,
      "name": "Soil_Hive_Corrupted_Brick",
      "rotation": 3
    },
    {
      "x": 10,
      "y": 1,
      "z": 21,
      "name": "Soil_Hive_Corrupted_Brick",
      "rotation": 3
    },
    {
      "x": 10,
      "y": 2,
      "z": 21,
      "name": "Soil_Hive_Corrupted_Brick",
      "rotation": 3
    },
    {
      "x": 10,
      "y": 3,
      "z": 21,
      "name": "Soil_Hive_Corrupted_Brick",
      "rotation": 3
    },
    {
      "x": 11,
      "y": 0,
      "z": -19,
      "name": "Soil_Hive_Corrupted_Brick",
      "rotation": 3
    },
    {
      "x": 11,
      "y": 1,
      "z": -19,
      "name": "Soil_Hive_Corrupted_Brick",
      "rotation": 3
    },
    {
      "x": 11,
      "y": 2,
      "z": -19,
      "name": "Soil_Hive_Corrupted_Brick",
      "rotation": 3
    },
    {
      "x": 11,
      "y": 3,
      "z": -19,
      "name": "Soil_Hive_Corrupted_Brick",
      "rotation": 3
    },
    {
      "x": 11,
      "y": 0,
      "z": -18,
      "name": "Rock_Bedrock"
    },
    {
      "x": 11,
      "y": 1,
      "z": -18,
      "name": "Rock_Bedrock"
    },
    {
      "x": 11,
      "y": 2,
      "z": -18,
      "name": "Rock_Bedrock"
    },
    {
      "x": 11,
      "y": 3,
      "z": -18,
      "name": "Rock_Bedrock"
    },
    {
      "x": 11,
      "y": 0,
      "z": 20,
      "name": "Rock_Bedrock"
    },
    {
      "x": 11,
      "y": 1,
      "z": 20,
      "name": "Rock_Bedrock"
    },
    {
      "x": 11,
      "y": 2,
      "z": 20,
      "name": "Rock_Bedrock"
    },
    {
      "x": 11,
      "y": 3,
      "z": 20,
      "name": "Rock_Bedrock"
    },
    {
      "x": 12,
      "y": 0,
      "z": -19,
      "name": "Soil_Hive_Corrupted_Brick",
      "rotation": 3
    },
    {
      "x": 12,
      "y": 1,
      "z": -19,
      "name": "Soil_Hive_Corrupted_Brick",
      "rotation": 3
    },
    {
      "x": 12,
      "y": 2,
      "z": -19,
      "name": "Soil_Hive_Corrupted_Brick",
      "rotation": 3
    },
    {
      "x": 12,
      "y": 3,
      "z": -19,
      "name": "Soil_Hive_Corrupted_Brick",
      "rotation": 3
    },
    {
      "x": 12,
      "y": 0,
      "z": -18,
      "name": "Rock_Bedrock"
    },
    {
      "x": 12,
      "y": 1,
      "z": -18,
      "name": "Rock_Bedrock"
    },
    {
      "x": 12,
      "y": 2,
      "z": -18,
      "name": "Rock_Bedrock"
    },
    {
      "x": 12,
      "y": 3,
      "z": -18,
      "name": "Rock_Bedrock"
    },
    {
      "x": 12,
      "y": 0,
      "z": 20,
      "name": "Rock_Bedrock"
    },
    {
      "x": 12,
      "y": 1,
      "z": 20,
      "name": "Rock_Bedrock"
    },
    {
      "x": 12,
      "y": 2,
      "z": 20,
      "name": "Rock_Bedrock"
    },
    {
      "x": 12,
      "y": 3,
      "z": 20,
      "name": "Rock_Bedrock"
    },
    {
      "x": 13,
      "y": 0,
      "z": -18,
      "name": "Rock_Bedrock"
    },
    {
      "x": 13,
      "y": 1,
      "z": -18,
      "name": "Rock_Bedrock"
    },
    {
      "x": 13,
      "y": 2,
      "z": -18,
      "name": "Rock_Bedrock"
    },
    {
      "x": 13,
      "y": 3,
      "z": -18,
      "name": "Rock_Bedrock"
    },
    {
      "x": 13,
      "y": 0,
      "z": 20,
      "name": "Rock_Bedrock"
    },
    {
      "x": 13,
      "y": 1,
      "z": 20,
      "name": "Rock_Bedrock"
    },
    {
      "x": 13,
      "y": 2,
      "z": 20,
      "name": "Rock_Bedrock"
    },
    {
      "x": 13,
      "y": 3,
      "z": 20,
      "name": "Rock_Bedrock"
    },
    {
      "x": 13,
      "y": 0,
      "z": 21,
      "name": "Soil_Hive_Corrupted_Brick",
      "rotation": 1
    },
    {
      "x": 13,
      "y": 1,
      "z": 21,
      "name": "Soil_Hive_Corrupted_Brick",
      "rotation": 1
    },
    {
      "x": 13,
      "y": 2,
      "z": 21,
      "name": "Soil_Hive_Corrupted_Brick",
      "rotation": 1
    },
    {
      "x": 13,
      "y": 3,
      "z": 21,
      "name": "Soil_Hive_Corrupted_Brick",
      "rotation": 1
    },
    {
      "x": 14,
      "y": 0,
      "z": -19,
      "name": "Soil_Hive_Corrupted_Brick",
      "rotation": 3
    },
    {
      "x": 14,
      "y": 1,
      "z": -19,
      "name": "Soil_Hive_Corrupted_Brick",
      "rotation": 3
    },
    {
      "x": 14,
      "y": 2,
      "z": -19,
      "name": "Soil_Hive_Corrupted_Brick",
      "rotation": 3
    },
    {
      "x": 14,
      "y": 3,
      "z": -19,
      "name": "Soil_Hive_Corrupted_Brick",
      "rotation": 3
    },
    {
      "x": 14,
      "y": 0,
      "z": -18,
      "name": "Rock_Bedrock"
    },
    {
      "x": 14,
      "y": 1,
      "z": -18,
      "name": "Rock_Bedrock"
    },
    {
      "x": 14,
      "y": 2,
      "z": -18,
      "name": "Rock_Bedrock"
    },
    {
      "x": 14,
      "y": 3,
      "z": -18,
      "name": "Rock_Bedrock"
    },
    {
      "x": 14,
      "y": 0,
      "z": 20,
      "name": "Rock_Bedrock"
    },
    {
      "x": 14,
      "y": 1,
      "z": 20,
      "name": "Rock_Bedrock"
    },
    {
      "x": 14,
      "y": 2,
      "z": 20,
      "name": "Rock_Bedrock"
    },
    {
      "x": 14,
      "y": 3,
      "z": 20,
      "name": "Rock_Bedrock"
    },
    {
      "x": 14,
      "y": 0,
      "z": 21,
      "name": "Soil_Hive_Corrupted_Brick",
      "rotation": 1
    },
    {
      "x": 14,
      "y": 1,
      "z": 21,
      "name": "Soil_Hive_Corrupted_Brick",
      "rotation": 1
    },
    {
      "x": 14,
      "y": 2,
      "z": 21,
      "name": "Soil_Hive_Corrupted_Brick",
      "rotation": 1
    },
    {
      "x": 14,
      "y": 3,
      "z": 21,
      "name": "Soil_Hive_Corrupted_Brick",
      "rotation": 1
    },
    {
      "x": 15,
      "y": 0,
      "z": -19,
      "name": "Soil_Hive_Corrupted_Brick",
      "rotation": 3
    },
    {
      "x": 15,
      "y": 1,
      "z": -19,
      "name": "Soil_Hive_Corrupted_Brick",
      "rotation": 3
    },
    {
      "x": 15,
      "y": 2,
      "z": -19,
      "name": "Soil_Hive_Corrupted_Brick",
      "rotation": 3
    },
    {
      "x": 15,
      "y": 3,
      "z": -19,
      "name": "Soil_Hive_Corrupted_Brick",
      "rotation": 3
    },
    {
      "x": 15,
      "y": 0,
      "z": -18,
      "name": "Rock_Bedrock"
    },
    {
      "x": 15,
      "y": 1,
      "z": -18,
      "name": "Rock_Bedrock"
    },
    {
      "x": 15,
      "y": 2,
      "z": -18,
      "name": "Rock_Bedrock"
    },
    {
      "x": 15,
      "y": 3,
      "z": -18,
      "name": "Rock_Bedrock"
    },
    {
      "x": 15,
      "y": 0,
      "z": 20,
      "name": "Rock_Bedrock"
    },
    {
      "x": 15,
      "y": 1,
      "z": 20,
      "name": "Rock_Bedrock"
    },
    {
      "x": 15,
      "y": 2,
      "z": 20,
      "name": "Rock_Bedrock"
    },
    {
      "x": 15,
      "y": 3,
      "z": 20,
      "name": "Rock_Bedrock"
    },
    {
      "x": 15,
      "y": 0,
      "z": 21,
      "name": "Soil_Hive_Corrupted_Brick",
      "rotation": 1
    },
    {
      "x": 15,
      "y": 1,
      "z": 21,
      "name": "Soil_Hive_Corrupted_Brick",
      "rotation": 1
    },
    {
      "x": 15,
      "y": 2,
      "z": 21,
      "name": "Soil_Hive_Corrupted_Brick",
      "rotation": 1
    },
    {
      "x": 15,
      "y": 3,
      "z": 21,
      "name": "Soil_Hive_Corrupted_Brick",
      "rotation": 1
    },
    {
      "x": 16,
      "y": 0,
      "z": -19,
      "name": "Soil_Hive_Corrupted_Brick",
      "rotation": 3
    },
    {
      "x": 16,
      "y": 1,
      "z": -19,
      "name": "Soil_Hive_Corrupted_Brick",
      "rotation": 3
    },
    {
      "x": 16,
      "y": 2,
      "z": -19,
      "name": "Soil_Hive_Corrupted_Brick",
      "rotation": 3
    },
    {
      "x": 16,
      "y": 3,
      "z": -19,
      "name": "Soil_Hive_Corrupted_Brick",
      "rotation": 3
    },
    {
      "x": 16,
      "y": 0,
      "z": -18,
      "name": "Rock_Bedrock"
    },
    {
      "x": 16,
      "y": 1,
      "z": -18,
      "name": "Rock_Bedrock"
    },
    {
      "x": 16,
      "y": 2,
      "z": -18,
      "name": "Rock_Bedrock"
    },
    {
      "x": 16,
      "y": 3,
      "z": -18,
      "name": "Rock_Bedrock"
    },
    {
      "x": 16,
      "y": 0,
      "z": 20,
      "name": "Rock_Bedrock"
    },
    {
      "x": 16,
      "y": 1,
      "z": 20,
      "name": "Rock_Bedrock"
    },
    {
      "x": 16,
      "y": 2,
      "z": 20,
      "name": "Rock_Bedrock"
    },
    {
      "x": 16,
      "y": 3,
      "z": 20,
      "name": "Rock_Bedrock"
    },
    {
      "x": 16,
      "y": 0,
      "z": 21,
      "name": "Soil_Hive_Corrupted_Brick",
      "rotation": 1
    },
    {
      "x": 16,
      "y": 1,
      "z": 21,
      "name": "Soil_Hive_Corrupted_Brick",
      "rotation": 1
    },
    {
      "x": 16,
      "y": 2,
      "z": 21,
      "name": "Soil_Hive_Corrupted_Brick",
      "rotation": 1
    },
    {
      "x": 16,
      "y": 3,
      "z": 21,
      "name": "Soil_Hive_Corrupted_Brick",
      "rotation": 1
    },
    {
      "x": 17,
      "y": 0,
      "z": -18,
      "name": "Rock_Bedrock"
    },
    {
      "x": 17,
      "y": 1,
      "z": -18,
      "name": "Rock_Bedrock"
    },
    {
      "x": 17,
      "y": 2,
      "z": -18,
      "name": "Rock_Bedrock"
    },
    {
      "x": 17,
      "y": 3,
      "z": -18,
      "name": "Rock_Bedrock"
    },
    {
      "x": 17,
      "y": 0,
      "z": 20,
      "name": "Rock_Bedrock"
    },
    {
      "x": 17,
      "y": 1,
      "z": 20,
      "name": "Rock_Bedrock"
    },
    {
      "x": 17,
      "y": 2,
      "z": 20,
      "name": "Rock_Bedrock"
    },
    {
      "x": 17,
      "y": 3,
      "z": 20,
      "name": "Rock_Bedrock"
    },
    {
      "x": 17,
      "y": 0,
      "z": 21,
      "name": "Soil_Hive_Corrupted_Brick",
      "rotation": 1
    },
    {
      "x": 17,
      "y": 1,
      "z": 21,
      "name": "Soil_Hive_Corrupted_Brick",
      "rotation": 1
    },
    {
      "x": 17,
      "y": 2,
      "z": 21,
      "name": "Soil_Hive_Corrupted_Brick",
      "rotation": 1
    },
    {
      "x": 17,
      "y": 3,
      "z": 21,
      "name": "Soil_Hive_Corrupted_Brick",
      "rotation": 1
    },
    {
      "x": 18,
      "y": 0,
      "z": -19,
      "name": "Soil_Hive_Corrupted_Brick",
      "rotation": 3
    },
    {
      "x": 18,
      "y": 1,
      "z": -19,
      "name": "Soil_Hive_Corrupted_Brick",
      "rotation": 3
    },
    {
      "x": 18,
      "y": 2,
      "z": -19,
      "name": "Soil_Hive_Corrupted_Brick",
      "rotation": 3
    },
    {
      "x": 18,
      "y": 3,
      "z": -19,
      "name": "Soil_Hive_Corrupted_Brick",
      "rotation": 3
    },
    {
      "x": 18,
      "y": 0,
      "z": -18,
      "name": "Rock_Bedrock"
    },
    {
      "x": 18,
      "y": 1,
      "z": -18,
      "name": "Rock_Bedrock"
    },
    {
      "x": 18,
      "y": 2,
      "z": -18,
      "name": "Rock_Bedrock"
    },
    {
      "x": 18,
      "y": 3,
      "z": -18,
      "name": "Rock_Bedrock"
    },
    {
      "x": 18,
      "y": 0,
      "z": 20,
      "name": "Rock_Bedrock"
    },
    {
      "x": 18,
      "y": 1,
      "z": 20,
      "name": "Rock_Bedrock"
    },
    {
      "x": 18,
      "y": 2,
      "z": 20,
      "name": "Rock_Bedrock"
    },
    {
      "x": 18,
      "y": 3,
      "z": 20,
      "name": "Rock_Bedrock"
    },
    {
      "x": 19,
      "y": 0,
      "z": -19,
      "name": "Soil_Hive_Corrupted_Brick",
      "rotation": 3
    },
    {
      "x": 19,
      "y": 1,
      "z": -19,
      "name": "Soil_Hive_Corrupted_Brick",
      "rotation": 3
    },
    {
      "x": 19,
      "y": 2,
      "z": -19,
      "name": "Soil_Hive_Corrupted_Brick",
      "rotation": 3
    },
    {
      "x": 19,
      "y": 3,
      "z": -19,
      "name": "Soil_Hive_Corrupted_Brick",
      "rotation": 3
    },
    {
      "x": 19,
      "y": 0,
      "z": -18,
      "name": "Rock_Bedrock"
    },
    {
      "x": 19,
      "y": 1,
      "z": -18,
      "name": "Rock_Bedrock"
    },
    {
      "x": 19,
      "y": 2,
      "z": -18,
      "name": "Rock_Bedrock"
    },
    {
      "x": 19,
      "y": 3,
      "z": -18,
      "name": "Rock_Bedrock"
    },
    {
      "x": 19,
      "y": 0,
      "z": 20,
      "name": "Rock_Bedrock"
    },
    {
      "x": 19,
      "y": 1,
      "z": 20,
      "name": "Rock_Bedrock"
    },
    {
      "x": 19,
      "y": 2,
      "z": 20,
      "name": "Rock_Bedrock"
    },
    {
      "x": 19,
      "y": 3,
      "z": 20,
      "name": "Rock_Bedrock"
    },
    {
      "x": 20,
      "y": 0,
      "z": -19,
      "name": "Soil_Hive_Corrupted_Brick",
      "rotation": 3
    },
    {
      "x": 20,
      "y": 1,
      "z": -19,
      "name": "Soil_Hive_Corrupted_Brick",
      "rotation": 3
    },
    {
      "x": 20,
      "y": 2,
      "z": -19,
      "name": "Soil_Hive_Corrupted_Brick",
      "rotation": 3
    },
    {
      "x": 20,
      "y": 3,
      "z": -19,
      "name": "Soil_Hive_Corrupted_Brick",
      "rotation": 3
    },
    {
      "x": 20,
      "y": 0,
      "z": -18,
      "name": "Rock_Bedrock"
    },
    {
      "x": 20,
      "y": 1,
      "z": -18,
      "name": "Rock_Bedrock"
    },
    {
      "x": 20,
      "y": 2,
      "z": -18,
      "name": "Rock_Bedrock"
    },
    {
      "x": 20,
      "y": 3,
      "z": -18,
      "name": "Rock_Bedrock"
    },
    {
      "x": 20,
      "y": 0,
      "z": -17,
      "name": "Rock_Bedrock"
    },
    {
      "x": 20,
      "y": 1,
      "z": -17,
      "name": "Rock_Bedrock"
    },
    {
      "x": 20,
      "y": 2,
      "z": -17,
      "name": "Rock_Bedrock"
    },
    {
      "x": 20,
      "y": 3,
      "z": -17,
      "name": "Rock_Bedrock"
    },
    {
      "x": 20,
      "y": 0,
      "z": -16,
      "name": "Rock_Bedrock"
    },
    {
      "x": 20,
      "y": 1,
      "z": -16,
      "name": "Rock_Bedrock"
    },
    {
      "x": 20,
      "y": 2,
      "z": -16,
      "name": "Rock_Bedrock"
    },
    {
      "x": 20,
      "y": 3,
      "z": -16,
      "name": "Rock_Bedrock"
    },
    {
      "x": 20,
      "y": 0,
      "z": -15,
      "name": "Rock_Bedrock"
    },
    {
      "x": 20,
      "y": 1,
      "z": -15,
      "name": "Rock_Bedrock"
    },
    {
      "x": 20,
      "y": 2,
      "z": -15,
      "name": "Rock_Bedrock"
    },
    {
      "x": 20,
      "y": 3,
      "z": -15,
      "name": "Rock_Bedrock"
    },
    {
      "x": 20,
      "y": 0,
      "z": -14,
      "name": "Rock_Bedrock"
    },
    {
      "x": 20,
      "y": 1,
      "z": -14,
      "name": "Rock_Bedrock"
    },
    {
      "x": 20,
      "y": 2,
      "z": -14,
      "name": "Rock_Bedrock"
    },
    {
      "x": 20,
      "y": 3,
      "z": -14,
      "name": "Rock_Bedrock"
    },
    {
      "x": 20,
      "y": 0,
      "z": -13,
      "name": "Rock_Bedrock"
    },
    {
      "x": 20,
      "y": 1,
      "z": -13,
      "name": "Rock_Bedrock"
    },
    {
      "x": 20,
      "y": 2,
      "z": -13,
      "name": "Rock_Bedrock"
    },
    {
      "x": 20,
      "y": 3,
      "z": -13,
      "name": "Rock_Bedrock"
    },
    {
      "x": 20,
      "y": 0,
      "z": -12,
      "name": "Rock_Bedrock"
    },
    {
      "x": 20,
      "y": 1,
      "z": -12,
      "name": "Rock_Bedrock"
    },
    {
      "x": 20,
      "y": 2,
      "z": -12,
      "name": "Rock_Bedrock"
    },
    {
      "x": 20,
      "y": 3,
      "z": -12,
      "name": "Rock_Bedrock"
    },
    {
      "x": 20,
      "y": 0,
      "z": -11,
      "name": "Rock_Bedrock"
    },
    {
      "x": 20,
      "y": 1,
      "z": -11,
      "name": "Rock_Bedrock"
    },
    {
      "x": 20,
      "y": 2,
      "z": -11,
      "name": "Rock_Bedrock"
    },
    {
      "x": 20,
      "y": 3,
      "z": -11,
      "name": "Rock_Bedrock"
    },
    {
      "x": 20,
      "y": 0,
      "z": -10,
      "name": "Rock_Bedrock"
    },
    {
      "x": 20,
      "y": 1,
      "z": -10,
      "name": "Rock_Bedrock"
    },
    {
      "x": 20,
      "y": 2,
      "z": -10,
      "name": "Rock_Bedrock"
    },
    {
      "x": 20,
      "y": 3,
      "z": -10,
      "name": "Rock_Bedrock"
    },
    {
      "x": 20,
      "y": 0,
      "z": -9,
      "name": "Rock_Bedrock"
    },
    {
      "x": 20,
      "y": 1,
      "z": -9,
      "name": "Rock_Bedrock"
    },
    {
      "x": 20,
      "y": 2,
      "z": -9,
      "name": "Rock_Bedrock"
    },
    {
      "x": 20,
      "y": 3,
      "z": -9,
      "name": "Rock_Bedrock"
    },
    {
      "x": 20,
      "y": 0,
      "z": -8,
      "name": "Rock_Bedrock"
    },
    {
      "x": 20,
      "y": 1,
      "z": -8,
      "name": "Rock_Bedrock"
    },
    {
      "x": 20,
      "y": 2,
      "z": -8,
      "name": "Rock_Bedrock"
    },
    {
      "x": 20,
      "y": 3,
      "z": -8,
      "name": "Rock_Bedrock"
    },
    {
      "x": 20,
      "y": 0,
      "z": -7,
      "name": "Rock_Bedrock"
    },
    {
      "x": 20,
      "y": 1,
      "z": -7,
      "name": "Rock_Bedrock"
    },
    {
      "x": 20,
      "y": 2,
      "z": -7,
      "name": "Rock_Bedrock"
    },
    {
      "x": 20,
      "y": 3,
      "z": -7,
      "name": "Rock_Bedrock"
    },
    {
      "x": 20,
      "y": 0,
      "z": -6,
      "name": "Rock_Bedrock"
    },
    {
      "x": 20,
      "y": 1,
      "z": -6,
      "name": "Rock_Bedrock"
    },
    {
      "x": 20,
      "y": 2,
      "z": -6,
      "name": "Rock_Bedrock"
    },
    {
      "x": 20,
      "y": 3,
      "z": -6,
      "name": "Rock_Bedrock"
    },
    {
      "x": 20,
      "y": 0,
      "z": -5,
      "name": "Rock_Bedrock"
    },
    {
      "x": 20,
      "y": 1,
      "z": -5,
      "name": "Rock_Bedrock"
    },
    {
      "x": 20,
      "y": 2,
      "z": -5,
      "name": "Rock_Bedrock"
    },
    {
      "x": 20,
      "y": 3,
      "z": -5,
      "name": "Rock_Bedrock"
    },
    {
      "x": 20,
      "y": 0,
      "z": -4,
      "name": "Rock_Bedrock"
    },
    {
      "x": 20,
      "y": 1,
      "z": -4,
      "name": "Rock_Bedrock"
    },
    {
      "x": 20,
      "y": 2,
      "z": -4,
      "name": "Rock_Bedrock"
    },
    {
      "x": 20,
      "y": 3,
      "z": -4,
      "name": "Rock_Bedrock"
    },
    {
      "x": 20,
      "y": 0,
      "z": -3,
      "name": "Rock_Bedrock"
    },
    {
      "x": 20,
      "y": 1,
      "z": -3,
      "name": "Rock_Bedrock"
    },
    {
      "x": 20,
      "y": 2,
      "z": -3,
      "name": "Rock_Bedrock"
    },
    {
      "x": 20,
      "y": 3,
      "z": -3,
      "name": "Rock_Bedrock"
    },
    {
      "x": 20,
      "y": 0,
      "z": -2,
      "name": "Rock_Bedrock"
    },
    {
      "x": 20,
      "y": 1,
      "z": -2,
      "name": "Rock_Bedrock"
    },
    {
      "x": 20,
      "y": 2,
      "z": -2,
      "name": "Rock_Bedrock"
    },
    {
      "x": 20,
      "y": 3,
      "z": -2,
      "name": "Rock_Bedrock"
    },
    {
      "x": 20,
      "y": 0,
      "z": -1,
      "name": "Rock_Bedrock"
    },
    {
      "x": 20,
      "y": 1,
      "z": -1,
      "name": "Rock_Bedrock"
    },
    {
      "x": 20,
      "y": 2,
      "z": -1,
      "name": "Rock_Bedrock"
    },
    {
      "x": 20,
      "y": 3,
      "z": -1,
      "name": "Rock_Bedrock"
    },
    {
      "x": 20,
      "y": 0,
      "z": 0,
      "name": "Rock_Bedrock"
    },
    {
      "x": 20,
      "y": 1,
      "z": 0,
      "name": "Rock_Bedrock"
    },
    {
      "x": 20,
      "y": 2,
      "z": 0,
      "name": "Rock_Bedrock"
    },
    {
      "x": 20,
      "y": 3,
      "z": 0,
      "name": "Rock_Bedrock"
    },
    {
      "x": 20,
      "y": 0,
      "z": 1,
      "name": "Rock_Bedrock"
    },
    {
      "x": 20,
      "y": 1,
      "z": 1,
      "name": "Rock_Bedrock"
    },
    {
      "x": 20,
      "y": 2,
      "z": 1,
      "name": "Rock_Bedrock"
    },
    {
      "x": 20,
      "y": 3,
      "z": 1,
      "name": "Rock_Bedrock"
    },
    {
      "x": 20,
      "y": 0,
      "z": 2,
      "name": "Rock_Bedrock"
    },
    {
      "x": 20,
      "y": 1,
      "z": 2,
      "name": "Rock_Bedrock"
    },
    {
      "x": 20,
      "y": 2,
      "z": 2,
      "name": "Rock_Bedrock"
    },
    {
      "x": 20,
      "y": 3,
      "z": 2,
      "name": "Rock_Bedrock"
    },
    {
      "x": 20,
      "y": 0,
      "z": 3,
      "name": "Rock_Bedrock"
    },
    {
      "x": 20,
      "y": 1,
      "z": 3,
      "name": "Rock_Bedrock"
    },
    {
      "x": 20,
      "y": 2,
      "z": 3,
      "name": "Rock_Bedrock"
    },
    {
      "x": 20,
      "y": 3,
      "z": 3,
      "name": "Rock_Bedrock"
    },
    {
      "x": 20,
      "y": 0,
      "z": 4,
      "name": "Rock_Bedrock"
    },
    {
      "x": 20,
      "y": 1,
      "z": 4,
      "name": "Rock_Bedrock"
    },
    {
      "x": 20,
      "y": 2,
      "z": 4,
      "name": "Rock_Bedrock"
    },
    {
      "x": 20,
      "y": 3,
      "z": 4,
      "name": "Rock_Bedrock"
    },
    {
      "x": 20,
      "y": 0,
      "z": 5,
      "name": "Rock_Bedrock"
    },
    {
      "x": 20,
      "y": 1,
      "z": 5,
      "name": "Rock_Bedrock"
    },
    {
      "x": 20,
      "y": 2,
      "z": 5,
      "name": "Rock_Bedrock"
    },
    {
      "x": 20,
      "y": 3,
      "z": 5,
      "name": "Rock_Bedrock"
    },
    {
      "x": 20,
      "y": 0,
      "z": 6,
      "name": "Rock_Bedrock"
    },
    {
      "x": 20,
      "y": 1,
      "z": 6,
      "name": "Rock_Bedrock"
    },
    {
      "x": 20,
      "y": 2,
      "z": 6,
      "name": "Rock_Bedrock"
    },
    {
      "x": 20,
      "y": 3,
      "z": 6,
      "name": "Rock_Bedrock"
    },
    {
      "x": 20,
      "y": 0,
      "z": 7,
      "name": "Rock_Bedrock"
    },
    {
      "x": 20,
      "y": 1,
      "z": 7,
      "name": "Rock_Bedrock"
    },
    {
      "x": 20,
      "y": 2,
      "z": 7,
      "name": "Rock_Bedrock"
    },
    {
      "x": 20,
      "y": 3,
      "z": 7,
      "name": "Rock_Bedrock"
    },
    {
      "x": 20,
      "y": 0,
      "z": 8,
      "name": "Rock_Bedrock"
    },
    {
      "x": 20,
      "y": 1,
      "z": 8,
      "name": "Rock_Bedrock"
    },
    {
      "x": 20,
      "y": 2,
      "z": 8,
      "name": "Rock_Bedrock"
    },
    {
      "x": 20,
      "y": 3,
      "z": 8,
      "name": "Rock_Bedrock"
    },
    {
      "x": 20,
      "y": 0,
      "z": 9,
      "name": "Rock_Bedrock"
    },
    {
      "x": 20,
      "y": 1,
      "z": 9,
      "name": "Rock_Bedrock"
    },
    {
      "x": 20,
      "y": 2,
      "z": 9,
      "name": "Rock_Bedrock"
    },
    {
      "x": 20,
      "y": 3,
      "z": 9,
      "name": "Rock_Bedrock"
    },
    {
      "x": 20,
      "y": 0,
      "z": 10,
      "name": "Rock_Bedrock"
    },
    {
      "x": 20,
      "y": 1,
      "z": 10,
      "name": "Rock_Bedrock"
    },
    {
      "x": 20,
      "y": 2,
      "z": 10,
      "name": "Rock_Bedrock"
    },
    {
      "x": 20,
      "y": 3,
      "z": 10,
      "name": "Rock_Bedrock"
    },
    {
      "x": 20,
      "y": 0,
      "z": 11,
      "name": "Rock_Bedrock"
    },
    {
      "x": 20,
      "y": 1,
      "z": 11,
      "name": "Rock_Bedrock"
    },
    {
      "x": 20,
      "y": 2,
      "z": 11,
      "name": "Rock_Bedrock"
    },
    {
      "x": 20,
      "y": 3,
      "z": 11,
      "name": "Rock_Bedrock"
    },
    {
      "x": 20,
      "y": 0,
      "z": 12,
      "name": "Rock_Bedrock"
    },
    {
      "x": 20,
      "y": 1,
      "z": 12,
      "name": "Rock_Bedrock"
    },
    {
      "x": 20,
      "y": 2,
      "z": 12,
      "name": "Rock_Bedrock"
    },
    {
      "x": 20,
      "y": 3,
      "z": 12,
      "name": "Rock_Bedrock"
    },
    {
      "x": 20,
      "y": 0,
      "z": 13,
      "name": "Rock_Bedrock"
    },
    {
      "x": 20,
      "y": 1,
      "z": 13,
      "name": "Rock_Bedrock"
    },
    {
      "x": 20,
      "y": 2,
      "z": 13,
      "name": "Rock_Bedrock"
    },
    {
      "x": 20,
      "y": 3,
      "z": 13,
      "name": "Rock_Bedrock"
    },
    {
      "x": 20,
      "y": 0,
      "z": 14,
      "name": "Rock_Bedrock"
    },
    {
      "x": 20,
      "y": 1,
      "z": 14,
      "name": "Rock_Bedrock"
    },
    {
      "x": 20,
      "y": 2,
      "z": 14,
      "name": "Rock_Bedrock"
    },
    {
      "x": 20,
      "y": 3,
      "z": 14,
      "name": "Rock_Bedrock"
    },
    {
      "x": 20,
      "y": 0,
      "z": 15,
      "name": "Rock_Bedrock"
    },
    {
      "x": 20,
      "y": 1,
      "z": 15,
      "name": "Rock_Bedrock"
    },
    {
      "x": 20,
      "y": 2,
      "z": 15,
      "name": "Rock_Bedrock"
    },
    {
      "x": 20,
      "y": 3,
      "z": 15,
      "name": "Rock_Bedrock"
    },
    {
      "x": 20,
      "y": 0,
      "z": 16,
      "name": "Rock_Bedrock"
    },
    {
      "x": 20,
      "y": 1,
      "z": 16,
      "name": "Rock_Bedrock"
    },
    {
      "x": 20,
      "y": 2,
      "z": 16,
      "name": "Rock_Bedrock"
    },
    {
      "x": 20,
      "y": 3,
      "z": 16,
      "name": "Rock_Bedrock"
    },
    {
      "x": 20,
      "y": 0,
      "z": 17,
      "name": "Rock_Bedrock"
    },
    {
      "x": 20,
      "y": 1,
      "z": 17,
      "name": "Rock_Bedrock"
    },
    {
      "x": 20,
      "y": 2,
      "z": 17,
      "name": "Rock_Bedrock"
    },
    {
      "x": 20,
      "y": 3,
      "z": 17,
      "name": "Rock_Bedrock"
    },
    {
      "x": 20,
      "y": 0,
      "z": 18,
      "name": "Rock_Bedrock"
    },
    {
      "x": 20,
      "y": 1,
      "z": 18,
      "name": "Rock_Bedrock"
    },
    {
      "x": 20,
      "y": 2,
      "z": 18,
      "name": "Rock_Bedrock"
    },
    {
      "x": 20,
      "y": 3,
      "z": 18,
      "name": "Rock_Bedrock"
    },
    {
      "x": 20,
      "y": 0,
      "z": 19,
      "name": "Rock_Bedrock"
    },
    {
      "x": 20,
      "y": 1,
      "z": 19,
      "name": "Rock_Bedrock"
    },
    {
      "x": 20,
      "y": 2,
      "z": 19,
      "name": "Rock_Bedrock"
    },
    {
      "x": 20,
      "y": 3,
      "z": 19,
      "name": "Rock_Bedrock"
    },
    {
      "x": 20,
      "y": 0,
      "z": 20,
      "name": "Rock_Bedrock"
    },
    {
      "x": 20,
      "y": 1,
      "z": 20,
      "name": "Rock_Bedrock"
    },
    {
      "x": 20,
      "y": 2,
      "z": 20,
      "name": "Rock_Bedrock"
    },
    {
      "x": 20,
      "y": 3,
      "z": 20,
      "name": "Rock_Bedrock"
    },
    {
      "x": 21,
      "y": 0,
      "z": -17,
      "name": "Soil_Hive_Corrupted_Brick"
    },
    {
      "x": 21,
      "y": 1,
      "z": -17,
      "name": "Soil_Hive_Corrupted_Brick"
    },
    {
      "x": 21,
      "y": 2,
      "z": -17,
      "name": "Soil_Hive_Corrupted_Brick"
    },
    {
      "x": 21,
      "y": 3,
      "z": -17,
      "name": "Soil_Hive_Corrupted_Brick"
    },
    {
      "x": 21,
      "y": 0,
      "z": -16,
      "name": "Soil_Hive_Corrupted_Brick"
    },
    {
      "x": 21,
      "y": 1,
      "z": -16,
      "name": "Soil_Hive_Corrupted_Brick"
    },
    {
      "x": 21,
      "y": 2,
      "z": -16,
      "name": "Soil_Hive_Corrupted_Brick"
    },
    {
      "x": 21,
      "y": 3,
      "z": -16,
      "name": "Soil_Hive_Corrupted_Brick"
    },
    {
      "x": 21,
      "y": 0,
      "z": -15,
      "name": "Soil_Hive_Corrupted_Brick"
    },
    {
      "x": 21,
      "y": 1,
      "z": -15,
      "name": "Soil_Hive_Corrupted_Brick"
    },
    {
      "x": 21,
      "y": 2,
      "z": -15,
      "name": "Soil_Hive_Corrupted_Brick"
    },
    {
      "x": 21,
      "y": 3,
      "z": -15,
      "name": "Soil_Hive_Corrupted_Brick"
    },
    {
      "x": 21,
      "y": 0,
      "z": -13,
      "name": "Soil_Hive_Corrupted_Brick"
    },
    {
      "x": 21,
      "y": 1,
      "z": -13,
      "name": "Soil_Hive_Corrupted_Brick"
    },
    {
      "x": 21,
      "y": 2,
      "z": -13,
      "name": "Soil_Hive_Corrupted_Brick"
    },
    {
      "x": 21,
      "y": 3,
      "z": -13,
      "name": "Soil_Hive_Corrupted_Brick"
    },
    {
      "x": 21,
      "y": 0,
      "z": -12,
      "name": "Soil_Hive_Corrupted_Brick"
    },
    {
      "x": 21,
      "y": 1,
      "z": -12,
      "name": "Soil_Hive_Corrupted_Brick"
    },
    {
      "x": 21,
      "y": 2,
      "z": -12,
      "name": "Soil_Hive_Corrupted_Brick"
    },
    {
      "x": 21,
      "y": 3,
      "z": -12,
      "name": "Soil_Hive_Corrupted_Brick"
    },
    {
      "x": 21,
      "y": 0,
      "z": -11,
      "name": "Soil_Hive_Corrupted_Brick"
    },
    {
      "x": 21,
      "y": 1,
      "z": -11,
      "name": "Soil_Hive_Corrupted_Brick"
    },
    {
      "x": 21,
      "y": 2,
      "z": -11,
      "name": "Soil_Hive_Corrupted_Brick"
    },
    {
      "x": 21,
      "y": 3,
      "z": -11,
      "name": "Soil_Hive_Corrupted_Brick"
    },
    {
      "x": 21,
      "y": 0,
      "z": -9,
      "name": "Soil_Hive_Corrupted_Brick"
    },
    {
      "x": 21,
      "y": 1,
      "z": -9,
      "name": "Soil_Hive_Corrupted_Brick"
    },
    {
      "x": 21,
      "y": 2,
      "z": -9,
      "name": "Soil_Hive_Corrupted_Brick"
    },
    {
      "x": 21,
      "y": 3,
      "z": -9,
      "name": "Soil_Hive_Corrupted_Brick"
    },
    {
      "x": 21,
      "y": 0,
      "z": -8,
      "name": "Soil_Hive_Corrupted_Brick"
    },
    {
      "x": 21,
      "y": 1,
      "z": -8,
      "name": "Soil_Hive_Corrupted_Brick"
    },
    {
      "x": 21,
      "y": 2,
      "z": -8,
      "name": "Soil_Hive_Corrupted_Brick"
    },
    {
      "x": 21,
      "y": 3,
      "z": -8,
      "name": "Soil_Hive_Corrupted_Brick"
    },
    {
      "x": 21,
      "y": 0,
      "z": -7,
      "name": "Soil_Hive_Corrupted_Brick"
    },
    {
      "x": 21,
      "y": 1,
      "z": -7,
      "name": "Soil_Hive_Corrupted_Brick"
    },
    {
      "x": 21,
      "y": 2,
      "z": -7,
      "name": "Soil_Hive_Corrupted_Brick"
    },
    {
      "x": 21,
      "y": 3,
      "z": -7,
      "name": "Soil_Hive_Corrupted_Brick"
    },
    {
      "x": 21,
      "y": 0,
      "z": -4,
      "name": "Soil_Hive_Corrupted_Brick"
    },
    {
      "x": 21,
      "y": 1,
      "z": -4,
      "name": "Soil_Hive_Corrupted_Brick"
    },
    {
      "x": 21,
      "y": 2,
      "z": -4,
      "name": "Soil_Hive_Corrupted_Brick"
    },
    {
      "x": 21,
      "y": 3,
      "z": -4,
      "name": "Soil_Hive_Corrupted_Brick"
    },
    {
      "x": 21,
      "y": 0,
      "z": -3,
      "name": "Soil_Hive_Corrupted_Brick"
    },
    {
      "x": 21,
      "y": 1,
      "z": -3,
      "name": "Soil_Hive_Corrupted_Brick"
    },
    {
      "x": 21,
      "y": 2,
      "z": -3,
      "name": "Soil_Hive_Corrupted_Brick"
    },
    {
      "x": 21,
      "y": 3,
      "z": -3,
      "name": "Soil_Hive_Corrupted_Brick"
    },
    {
      "x": 21,
      "y": 0,
      "z": -2,
      "name": "Soil_Hive_Corrupted_Brick"
    },
    {
      "x": 21,
      "y": 1,
      "z": -2,
      "name": "Soil_Hive_Corrupted_Brick"
    },
    {
      "x": 21,
      "y": 2,
      "z": -2,
      "name": "Soil_Hive_Corrupted_Brick"
    },
    {
      "x": 21,
      "y": 3,
      "z": -2,
      "name": "Soil_Hive_Corrupted_Brick"
    },
    {
      "x": 21,
      "y": 0,
      "z": 0,
      "name": "Soil_Hive_Corrupted_Brick",
      "rotation": 2
    },
    {
      "x": 21,
      "y": 1,
      "z": 0,
      "name": "Soil_Hive_Corrupted_Brick",
      "rotation": 2
    },
    {
      "x": 21,
      "y": 2,
      "z": 0,
      "name": "Soil_Hive_Corrupted_Brick",
      "rotation": 2
    },
    {
      "x": 21,
      "y": 3,
      "z": 0,
